Workbook
Name LechGioMayVsDB: ThamSo!$B$4
Name NguongCursorNgay: ThamSo!$B$7
Name NguongDoanhThuRatCao: ThamSo!$B$10
Name NguongDoanhThuTot: ThamSo!$B$11
Name NguongViewNgay: ThamSo!$B$8
Name PhatMatThe: ThamSo!$B$9
Name PhutMienPhi: ThamSo!$B$5
Name PhutMoiBlock: ThamSo!$B$6
Name ThoiDiemNap: ThamSo!$B$2
Name ThoiDiemTinh: ThamSo!$B$3

Sheet HuongDan
A1: DỮ LIỆU MẪU QuanLyBaiDoXe — FILE NGUỒN CHUẨN (MASTER)
A2: File này là nguồn chuẩn của dữ liệu mẫu
A3: Sửa dữ liệu ở đây (không sửa tay file SQL), lưu bằng Excel/LibreOffice để có giá trị đã tính, rồi sinh lại seed.
A5: Màu header
A6: • Xanh đậm = cột DB nhập tay (chữ xanh dương). • Xanh nhạt = cột nhập phụ, không phải cột DB (mốc thời gian, mật khẩu mẫu, STT…).
A7: • Cam = cột DB DẪN XUẤT bằng công thức — không nhập tay; seed ghi giá trị tính được. • Xanh lá = cột phụ / cờ kiểm tra KT_*.
A8: • Rê chuột vào header để xem kiểu SQL, ràng buộc và đối tượng SQL tương ứng.
A10: Ràng buộc
A11: • Data Validation chặn khi nhập: danh sách trạng thái, khóa ngoại (chọn từ sheet cha), độ dài theo VARCHAR(n), số dương.
A12: • Cờ KT_* kiểm tra cả dữ liệu đã có: PK, UNIQUE, FK, CHECK, định dạng mã, quy tắc nghiệp vụ. Tổng hợp ở sheet KiemTra — phải ĐẠT hết trước khi sinh seed.
A13: • Sheet LechLogicDB liệt kê các quy tắc của file này mà code/DB hiện chưa thực thi (chưa sửa, chỉ ghi nhận).
A15: Thời gian
... A23: • Vé ALL gửi được mọi bãi; vé gắn bãi chỉ gửi tại bãi đó; thẻ lượt chỉ dùng tại bãi phát hành.

Sheet ThamSo
A1: Tham số | B1: Giá trị | C1: Nguồn logic (SQL) | D1: Ghi chú
A2: ThoiDiemNap | B2: 46296.451 | C2: GETDATE() khi chạy seed | D2: Gốc của các mốc thời gian tương đối (lượt đang đỗ, vé V0007). Khi sinh SQL, các dòng tương đối được viết thành DATEADD(..., GETDATE()). Giờ theo SQL Server (container Docker chạy UTC).
A3: ThoiDiemTinh | B3: =ThoiDiemNap -> 46296.451 | C3: GETDATE() khi truy vấn | D3: Thời điểm đánh giá công thức phụ thuộc thời gian (tiền tạm tính xe đang đỗ, số ngày còn lại của vé). Mặc định = ThoiDiemNap; nhập ngày giờ khác để mô phỏng, hoặc =NOW()-LechGioMayVsDB/24.
A4: LechGioMayVsDB | B4: 7 | C4: Múi giờ | D4: Giờ máy mở file trừ giờ SQL Server (Việt Nam UTC+7, SQL Server trong Docker UTC).
A5: PhutMienPhi | B5: 15 | C5: f_TinhTienGuiXe | D5: Đỗ <= 15 phút miễn phí.
A6: PhutMoiBlock | B6: 60 | C6: f_TinhTienGuiXe | D6: Làm tròn lên block: CEILING(SoPhut / 60).
A7: NguongCursorNgay | B7: 3 | C7: sp_DemoCanhBaoHanTheThang | D7: Còn <= 3 ngày: cảnh báo nhắc nộp phí.
A8: NguongViewNgay | B8: 7 | C8: vw_Report_VeThangSapHetHan | D8: View liệt kê vé còn <= 7 ngày (gồm vé đã quá hạn).
A9: PhatMatThe | B9: 50000 | C9: trg_LogLichSuSuCo / sp_BaoMatThe | D9: Phí phạt đền bù thẻ vật lý khi báo mất.
A10: NguongDoanhThuRatCao | B10: 10000000 | C10: sp_DemoTongKetDoanhThuChuoi | D10: Tổng doanh thu >= ngưỡng: 'Hiệu quả rất cao'.
A11: NguongDoanhThuTot | B11: 2000000 | C11: sp_DemoTongKetDoanhThuChuoi | D11: Tổng doanh thu >= ngưỡng: 'Hiệu quả tốt'.

Sheet KiemTra
A1: Sheet | B1: Quy tắc | C1: Ràng buộc / đối tượng SQL | D1: Số dòng LỆCH | E1: Kết quả
A2: BAI_DO_XE | B2: KT_PK | C2: PK_BAI_DO_XE. | D2: =COUNTIF(BAI_DO_XE!$M$2:$M$1000,"LỆCH") -> 0 | E2: =IF(D2=0,"ĐẠT","LỆCH") -> ĐẠT
A3: BAI_DO_XE | B3: KT_TenBaiDuyNhat | C3: UQ_TenBai. | D3: =COUNTIF(BAI_DO_XE!$N$2:$N$1000,"LỆCH") -> 0 | E3: =IF(D3=0,"ĐẠT","LỆCH") -> ĐẠT
A4: BAI_DO_XE | B4: KT_DinhDangMa | C4: Mã bãi dạng BAI_xx. | D4: =COUNTIF(BAI_DO_XE!$O$2:$O$1000,"LỆCH") -> 0 | E4: =IF(D4=0,"ĐẠT","LỆCH") -> ĐẠT
A5: BAI_DO_XE | B5: KT_SucChuaDuong | C5: CK_SucChua: SucChua > 0 (bãi phải có ô đỗ). | D5: =COUNTIF(BAI_DO_XE!$P$2:$P$1000,"LỆCH") -> 0 | E5: =IF(D5=0,"ĐẠT","LỆCH") -> ĐẠT
A6: BAI_DO_XE | B6: KT_KhongVuotSucChua | C6: CK_SoLuongHienTai. | D6: =COUNTIF(BAI_DO_XE!$Q$2:$Q$1000,"LỆCH") -> 0 | E6: =IF(D6=0,"ĐẠT","LỆCH") -> ĐẠT
A7: NHAN_VIEN | B7: KT_PK | C7: PK_NHAN_VIEN. | D7: =COUNTIF(NHAN_VIEN!$I$2:$I$1000,"LỆCH") -> 0 | E7: =IF(D7=0,"ĐẠT","LỆCH") -> ĐẠT
A8: NHAN_VIEN | B8: KT_DinhDangMa | C8: Mã NV###. | D8: =COUNTIF(NHAN_VIEN!$J$2:$J$1000,"LỆCH") -> 0 | E8: =IF(D8=0,"ĐẠT","LỆCH") -> ĐẠT
A9: NHAN_VIEN | B9: KT_SDTDuyNhat | C9: UQ_NhanVien_SDT. | D9: =COUNTIF(NHAN_VIEN!$K$2:$K$1000,"LỆCH") -> 0 | E9: =IF(D9=0,"ĐẠT","LỆCH") -> ĐẠT
A10: NHAN_VIEN | B10: KT_EmailDuyNhat | C10: UQ_NhanVien_Email. | D10: =COUNTIF(NHAN_VIEN!$L$2:$L$1000,"LỆCH") -> 0 | E10: =IF(D10=0,"ĐẠT","LỆCH") -> ĐẠT
A11: NHAN_VIEN | B11: KT_FK_MaBai | C11: FK_NhanVien_BaiDoXe. | D11: =COUNTIF(NHAN_VIEN!$M$2:$M$1000,"LỆCH") -> 0 | E11: =IF(D11=0,"ĐẠT","LỆCH") -> ĐẠT
A12: NHAN_VIEN | B12: KT_PhamViTheoChucVu | C12: Giám đốc phụ trách toàn chuỗi (MaBai trống); Quản lý bãi / Bảo vệ phải gắn một bãi. | D12: =COUNTIF(NHAN_VIEN!$N$2:$N$1000,"LỆCH") -> 0 | E12: =IF(D12=0,"ĐẠT","LỆCH") -> ĐẠT
A13: TAI_KHOAN | B13: KT_PK | C13: PK_TAI_KHOAN. | D13: =COUNTIF(TAI_KHOAN!$I$2:$I$1000,"LỆCH") -> 0 | E13: =IF(D13=0,"ĐẠT","LỆCH") -> ĐẠT
A14: TAI_KHOAN | B14: KT_FK_MaNV | C14: FK_TaiKhoan_NhanVien. | D14: =COUNTIF(TAI_KHOAN!$J$2:$J$1000,"LỆCH") -> 0 | E14: =IF(D14=0,"ĐẠT","LỆCH") -> ĐẠT
A15: TAI_KHOAN | B15: KT_DoDaiHash | C15: SHA-256 hex 64 ký tự. | D15: =COUNTIF(TAI_KHOAN!$K$2:$K$1000,"LỆCH") -> 0 | E15: =IF(D15=0,"ĐẠT","LỆCH") -> ĐẠT
A16: LOAI_XE | B16: KT_PK | C16: PK_LOAI_XE (MaLoaiXe, MaBai). | D16: =COUNTIF(LOAI_XE!$I$2:$I$1000,"LỆCH") -> 0 | E16: =IF(D16=0,"ĐẠT","LỆCH") -> ĐẠT
A17: LOAI_XE | B17: KT_FK_MaBai | C17: FK_LoaiXe_BaiDoXe. | D17: =COUNTIF(LOAI_XE!$J$2:$J$1000,"LỆCH") -> 0 | E17: =IF(D17=0,"ĐẠT","LỆCH") -> ĐẠT
A18: LOAI_XE | B18: KT_GiaDuong | C18: CK_DonGiaGio, CK_GiaVeThang. | D18: =COUNTIF(LOAI_XE!$K$2:$K$1000,"LỆCH") -> 0 | E18: =IF(D18=0,"ĐẠT","LỆCH") -> ĐẠT
A19: VI_TRI_DO | B19: KT_PK | C19: PK_VI_TRI_DO. | D19: =COUNTIF(VI_TRI_DO!$G$2:$G$1000,"LỆCH") -> 0 | E19: =IF(D19=0,"ĐẠT","LỆCH") -> ĐẠT
A20: VI_TRI_DO | B20: KT_DinhDangMa | C20: Mã ô = <mã bãi bỏ 'BAI_'>_<MaLoaiXe>_<số>. | D20: =COUNTIF(VI_TRI_DO!$H$2:$H$1000,"LỆCH") -> 0 | E20: =IF(D20=0,"ĐẠT","LỆCH") -> ĐẠT
A21: VI_TRI_DO | B21: KT_FK_LoaiXeTaiBai | C21: FK_ViTriDo_LoaiXe. | D21: =COUNTIF(VI_TRI_DO!$I$2:$I$1000,"LỆCH") -> 0 | E21: =IF(D21=0,"ĐẠT","LỆCH") -> ĐẠT
A22: VI_TRI_DO | B22: KT_DoDaiKhuVuc | C22: KhuVuc NVARCHAR(20). | D22: =COUNTIF(VI_TRI_DO!$J$2:$J$1000,"LỆCH") -> 0 | E22: =IF(D22=0,"ĐẠT","LỆCH") -> ĐẠT
A23: VI_TRI_DO | B23: KT_MotXeMotO | C23: Một ô chỉ chứa tối đa 1 xe đang đỗ. | D23: =COUNTIF(VI_TRI_DO!$K$2:$K$1000,"LỆCH") -> 0 | E23: =IF(D23=0,"ĐẠT","LỆCH") -> ĐẠT
A24: THE_XE | B24: KT_PK | C24: PK_THE_XE. | D24: =COUNTIF(THE_XE!$N$2:$N$1000,"LỆCH") -> 0 | E24: =IF(D24=0,"ĐẠT","LỆCH") -> ĐẠT
A25: THE_XE | B25: KT_DinhDangMa | C25: Mã THE####. | D25: =COUNTIF(THE_XE!$O$2:$O$1000,"LỆCH") -> 0 | E25: =IF(D25=0,"ĐẠT","LỆCH") -> ĐẠT
A26: THE_XE | B26: KT_FK_MaBai | C26: FK_TheXe_BaiDoXe. | D26: =COUNTIF(THE_XE!$P$2:$P$1000,"LỆCH") -> 0 | E26: =IF(D26=0,"ĐẠT","LỆCH") -> ĐẠT
A27: THE_XE | B27: KT_TheThangCoVe | C27: Thẻ loại Tháng phải gắn một vé tháng. | D27: =COUNTIF(THE_XE!$Q$2:$Q$1000,"LỆCH") -> 0 | E27: =IF(D27=0,"ĐẠT","LỆCH") -> ĐẠT
A28: THE_XE | B28: KT_MotLuotMo | C28: Mỗi thẻ tối đa 1 lượt đang mở. | D28: =COUNTIF(THE_XE!$R$2:$R$1000,"LỆCH") -> 0 | E28: =IF(D28=0,"ĐẠT","LỆCH") -> ĐẠT
A29: THE_XE | B29: KT_TheHongKhongDangDo | C29: Thẻ khóa/mất không có lượt đang mở. | D29: =COUNTIF(THE_XE!$S$2:$S$1000,"LỆCH") -> 0 | E29: =IF(D29=0,"ĐẠT","LỆCH") -> ĐẠT
A30: KHACH_HANG | B30: KT_PK | C30: PK_KHACH_HANG. | D30: =COUNTIF(KHACH_HANG!$G$2:$G$1000,"LỆCH") -> 0 | E30: =IF(D30=0,"ĐẠT","LỆCH") -> ĐẠT
A31: KHACH_HANG | B31: KT_DinhDangMa | C31: Mã KH####. | D31: =COUNTIF(KHACH_HANG!$H$2:$H$1000,"LỆCH") -> 0 | E31: =IF(D31=0,"ĐẠT","LỆCH") -> ĐẠT
A32: KHACH_HANG | B32: KT_SDTDuyNhat | C32: UQ_KhachHang_SDT. | D32: =COUNTIF(KHACH_HANG!$I$2:$I$1000,"LỆCH") -> 0 | E32: =IF(D32=0,"ĐẠT","LỆCH") -> ĐẠT
A33: KHACH_HANG | B33: KT_EmailDuyNhat | C33: UQ_KhachHang_Email. | D33: =COUNTIF(KHACH_HANG!$J$2:$J$1000,"LỆCH") -> 0 | E33: =IF(D33=0,"ĐẠT","LỆCH") -> ĐẠT
A34: KHACH_HANG | B34: KT_CCCDDuyNhat | C34: UQ_KhachHang_CMND. | D34: =COUNTIF(KHACH_HANG!$K$2:$K$1000,"LỆCH") -> 0 | E34: =IF(D34=0,"ĐẠT","LỆCH") -> ĐẠT
A35: KHACH_HANG | B35: KT_CCCD12So | C35: CCCD 12 chữ số. | D35: =COUNTIF(KHACH_HANG!$L$2:$L$1000,"LỆCH") -> 0 | E35: =IF(D35=0,"ĐẠT","LỆCH") -> ĐẠT
A36: VE_THANG | B36: KT_PK | C36: PK_VE_THANG. | D36: =COUNTIF(VE_THANG!$R$2:$R$1000,"LỆCH") -> 0 | E36: =IF(D36=0,"ĐẠT","LỆCH") -> ĐẠT
A37: VE_THANG | B37: KT_DinhDangMa | C37: Mã V####. | D37: =COUNTIF(VE_THANG!$S$2:$S$1000,"LỆCH") -> 0 | E37: =IF(D37=0,"ĐẠT","LỆCH") -> ĐẠT
A38: VE_THANG | B38: KT_MaTheDuyNhat | C38: UQ_VeThang_MaThe. | D38: =COUNTIF(VE_THANG!$T$2:$T$1000,"LỆCH") -> 0 | E38: =IF(D38=0,"ĐẠT","LỆCH") -> ĐẠT
A39: VE_THANG | B39: KT_FK | C39: FK_VeThang_TheXe, FK_VeThang_KhachHang. | D39: =COUNTIF(VE_THANG!$U$2:$U$1000,"LỆCH") -> 0 | E39: =IF(D39=0,"ĐẠT","LỆCH") -> ĐẠT
A40: VE_THANG | B40: KT_TheLoaiThang | C40: Vé gắn thẻ loại Tháng. | D40: =COUNTIF(VE_THANG!$V$2:$V$1000,"LỆCH") -> 0 | E40: =IF(D40=0,"ĐẠT","LỆCH") -> ĐẠT
...

Sheet BAI_DO_XE
A1: MaBai | B1: TenBai | C1: DiaChi | D1: SucChua | E1: SoLuongHienTai | F1: SoChoTrong | G1: TyLeLapDay | H1: DoanhThuLuot | I1: DoanhThuThang | J1: TongDoanhThu | K1: DanhGiaHieuQua | L1: XepHangDoanhThu | M1: KT_PK | N1: KT_TenBaiDuyNhat | O1: KT_DinhDangMa | P1: KT_SucChuaDuong | Q1: KT_KhongVuotSucChua
A2: BAI_BT | B2: Bãi xe Landmark 81 | C2: Số 208 Nguyễn Hữu Cảnh, Phường 22, Bình Thạnh, TP.HCM | D2: =COUNTIF(VI_TRI_DO!$E$2:$E$1000,A2) -> 12 | E2: =SUMPRODUCT((LUOT_GUI!$H$2:$H$1000=A2)*(LEN(LUOT_GUI!$E$2:$E$1000)=0)) -> 1 | F2: =D2-E2 -> 11 | G2: =IF(D2>0,E2/D2,0) -> 0.083333333 | H2: =SUMIFS(LUOT_GUI!$G$2:$G$1000,LUOT_GUI!$H$2:$H$1000,A2) -> 77000 | I2: =SUMIFS(HOA_DON_VE_THANG!$E$2:$E$1000,HOA_DON_VE_THANG!$F$2:$F$1000,A2) -> 28800000 | J2: =H2+I2 -> 28877000 | K2: =IF(J2>=NguongDoanhThuRatCao,"Hiệu quả rất cao (Doanh thu > 10 triệu)",IF(J2>=NguongDoanhThuTot,"Hiệu quả tốt","Cần đẩy mạnh khai thác thêm lượt gửi")) -> Hiệu quả rất cao (Doanh thu > 10 triệu) | L2: =RANK(J2,$J$2:$J$6,0) -> 1 | M2: =IF(SUMPRODUCT(--(BAI_DO_XE!$A$2:$A$1000=A2))=1,"ĐẠT","LỆCH") -> ĐẠT | N2: =IF(SUMPRODUCT(--(BAI_DO_XE!$B$2:$B$1000=B2))=1,"ĐẠT","LỆCH") -> ĐẠT | O2: =IF(LEFT(A2,4)="BAI_","ĐẠT","LỆCH") -> ĐẠT | P2: =IF(D2>0,"ĐẠT","LỆCH") -> ĐẠT | Q2: =IF(E2<=D2,"ĐẠT","LỆCH") -> ĐẠT
A3: BAI_Q1 | B3: Bãi xe Lê Lai - Bến Thành | C3: Số 26 Lê Lai, Phường Bến Thành, Quận 1, TP.HCM | D3: =COUNTIF(VI_TRI_DO!$E$2:$E$1000,A3) -> 12 | E3: =SUMPRODUCT((LUOT_GUI!$H$2:$H$1000=A3)*(LEN(LUOT_GUI!$E$2:$E$1000)=0)) -> 2 | F3: =D3-E3 -> 10 | G3: =IF(D3>0,E3/D3,0) -> 0.16666667 | H3: =SUMIFS(LUOT_GUI!$G$2:$G$1000,LUOT_GUI!$H$2:$H$1000,A3) -> 174000 | I3: =SUMIFS(HOA_DON_VE_THANG!$E$2:$E$1000,HOA_DON_VE_THANG!$F$2:$F$1000,A3) -> 18360000 | J3: =H3+I3 -> 18534000 | K3: =IF(J3>=NguongDoanhThuRatCao,"Hiệu quả rất cao (Doanh thu > 10 triệu)",IF(J3>=NguongDoanhThuTot,"Hiệu quả tốt","Cần đẩy mạnh khai thác thêm lượt gửi")) -> Hiệu quả rất cao (Doanh thu > 10 triệu) | L3: =RANK(J3,$J$2:$J$6,0) -> 3 | M3: =IF(SUMPRODUCT(--(BAI_DO_XE!$A$2:$A$1000=A3))=1,"ĐẠT","LỆCH") -> ĐẠT | N3: =IF(SUMPRODUCT(--(BAI_DO_XE!$B$2:$B$1000=B3))=1,"ĐẠT","LỆCH") -> ĐẠT | O3: =IF(LEFT(A3,4)="BAI_","ĐẠT","LỆCH") -> ĐẠT | P3: =IF(D3>0,"ĐẠT","LỆCH") -> ĐẠT | Q3: =IF(E3<=D3,"ĐẠT","LỆCH") -> ĐẠT
A4: BAI_Q3 | B4: Bãi xe Hai Bà Trưng | C4: Số 180 Hai Bà Trưng, Phường Đa Kao, Quận 3, TP.HCM | D4: =COUNTIF(VI_TRI_DO!$E$2:$E$1000,A4) -> 10 | E4: =SUMPRODUCT((LUOT_GUI!$H$2:$H$1000=A4)*(LEN(LUOT_GUI!$E$2:$E$1000)=0)) -> 1 | F4: =D4-E4 -> 9 | G4: =IF(D4>0,E4/D4,0) -> 0.1 | H4: =SUMIFS(LUOT_GUI!$G$2:$G$1000,LUOT_GUI!$H$2:$H$1000,A4) -> 15000 | I4: =SUMIFS(HOA_DON_VE_THANG!$E$2:$E$1000,HOA_DON_VE_THANG!$F$2:$F$1000,A4) -> 15150000 | J4: =H4+I4 -> 15165000 | K4: =IF(J4>=NguongDoanhThuRatCao,"Hiệu quả rất cao (Doanh thu > 10 triệu)",IF(J4>=NguongDoanhThuTot,"Hiệu quả tốt","Cần đẩy mạnh khai thác thêm lượt gửi")) -> Hiệu quả rất cao (Doanh thu > 10 triệu) | L4: =RANK(J4,$J$2:$J$6,0) -> 4 | M4: =IF(SUMPRODUCT(--(BAI_DO_XE!$A$2:$A$1000=A4))=1,"ĐẠT","LỆCH") -> ĐẠT | N4: =IF(SUMPRODUCT(--(BAI_DO_XE!$B$2:$B$1000=B4))=1,"ĐẠT","LỆCH") -> ĐẠT | O4: =IF(LEFT(A4,4)="BAI_","ĐẠT","LỆCH") -> ĐẠT | P4: =IF(D4>0,"ĐẠT","LỆCH") -> ĐẠT | Q4: =IF(E4<=D4,"ĐẠT","LỆCH") -> ĐẠT
A5: BAI_Q7 | B5: Bãi xe SC VivoCity | C5: Số 1058 Nguyễn Văn Linh, Phường Tân Phong, Quận 7, TP.HCM | D5: =COUNTIF(VI_TRI_DO!$E$2:$E$1000,A5) -> 12 | E5: =SUMPRODUCT((LUOT_GUI!$H$2:$H$1000=A5)*(LEN(LUOT_GUI!$E$2:$E$1000)=0)) -> 2 | F5: =D5-E5 -> 10 | G5: =IF(D5>0,E5/D5,0) -> 0.16666667 | H5: =SUMIFS(LUOT_GUI!$G$2:$G$1000,LUOT_GUI!$H$2:$H$1000,A5) -> 20000 | I5: =SUMIFS(HOA_DON_VE_THANG!$E$2:$E$1000,HOA_DON_VE_THANG!$F$2:$F$1000,A5) -> 11220000 | J5: =H5+I5 -> 11240000 | K5: =IF(J5>=NguongDoanhThuRatCao,"Hiệu quả rất cao (Doanh thu > 10 triệu)",IF(J5>=NguongDoanhThuTot,"Hiệu quả tốt","Cần đẩy mạnh khai thác thêm lượt gửi")) -> Hiệu quả rất cao (Doanh thu > 10 triệu) | L5: =RANK(J5,$J$2:$J$6,0) -> 5 | M5: =IF(SUMPRODUCT(--(BAI_DO_XE!$A$2:$A$1000=A5))=1,"ĐẠT","LỆCH") -> ĐẠT | N5: =IF(SUMPRODUCT(--(BAI_DO_XE!$B$2:$B$1000=B5))=1,"ĐẠT","LỆCH") -> ĐẠT | O5: =IF(LEFT(A5,4)="BAI_","ĐẠT","LỆCH") -> ĐẠT | P5: =IF(D5>0,"ĐẠT","LỆCH") -> ĐẠT | Q5: =IF(E5<=D5,"ĐẠT","LỆCH") -> ĐẠT
A6: BAI_TB | B6: Bãi xe TCP Park - Sân bay Tân Sơn Nhất | C6: Cạnh nhà ga quốc nội, Cảng HKQT Tân Sơn Nhất, Phường 2, Quận Tân Bình, TP.HCM | D6: =COUNTIF(VI_TRI_DO!$E$2:$E$1000,A6) -> 14 | E6: =SUMPRODUCT((LUOT_GUI!$H$2:$H$1000=A6)*(LEN(LUOT_GUI!$E$2:$E$1000)=0)) -> 3 | F6: =D6-E6 -> 11 | G6: =IF(D6>0,E6/D6,0) -> 0.21428571 | H6: =SUMIFS(LUOT_GUI!$G$2:$G$1000,LUOT_GUI!$H$2:$H$1000,A6) -> 165000 | I6: =SUMIFS(HOA_DON_VE_THANG!$E$2:$E$1000,HOA_DON_VE_THANG!$F$2:$F$1000,A6) -> 19400000 | J6: =H6+I6 -> 19565000 | K6: =IF(J6>=NguongDoanhThuRatCao,"Hiệu quả rất cao (Doanh thu > 10 triệu)",IF(J6>=NguongDoanhThuTot,"Hiệu quả tốt","Cần đẩy mạnh khai thác thêm lượt gửi")) -> Hiệu quả rất cao (Doanh thu > 10 triệu) | L6: =RANK(J6,$J$2:$J$6,0) -> 2 | M6: =IF(SUMPRODUCT(--(BAI_DO_XE!$A$2:$A$1000=A6))=1,"ĐẠT","LỆCH") -> ĐẠT | N6: =IF(SUMPRODUCT(--(BAI_DO_XE!$B$2:$B$1000=B6))=1,"ĐẠT","LỆCH") -> ĐẠT | O6: =IF(LEFT(A6,4)="BAI_","ĐẠT","LỆCH") -> ĐẠT | P6: =IF(D6>0,"ĐẠT","LỆCH") -> ĐẠT | Q6: =IF(E6<=D6,"ĐẠT","LỆCH") -> ĐẠT

Sheet NHAN_VIEN
A1: MaNV | B1: HoTen | C1: ChucVu | D1: SDT | E1: Email | F1: MaBai | G1: TenBaiPhuTrach | H1: SoTaiKhoan | I1: KT_PK | J1: KT_DinhDangMa | K1: KT_SDTDuyNhat | L1: KT_EmailDuyNhat | M1: KT_FK_MaBai | N1: KT_PhamViTheoChucVu
A2: NV001 | B2: Nguyễn Hữu Trí | C2: Giám đốc điều hành | D2: 0901000001 | E2: tri.nguyen@smartparking.vn | G2: =IF(LEN(F2)=0,"Toàn chuỗi",INDEX(BAI_DO_XE!$B$2:$B$1000,MATCH(F2,BAI_DO_XE!$A$2:$A$1000,0))) -> Toàn chuỗi | H2: =COUNTIF(TAI_KHOAN!$C$2:$C$1000,A2) -> 1 | I2: =IF(SUMPRODUCT(--(NHAN_VIEN!$A$2:$A$1000=A2))=1,"ĐẠT","LỆCH") -> ĐẠT | J2: =IF(AND(LEN(A2)=5,LEFT(A2,2)="NV",ISNUMBER(-MID(A2,3,3)),ISERROR(FIND(".",MID(A2,3,3)))),"ĐẠT","LỆCH") -> ĐẠT | K2: =IF(SUMPRODUCT(--(NHAN_VIEN!$D$2:$D$1000=D2))=1,"ĐẠT","LỆCH") -> ĐẠT | L2: =IF(LEN(E2)=0,"ĐẠT",IF(SUMPRODUCT(--(NHAN_VIEN!$E$2:$E$1000=E2))=1,"ĐẠT","LỆCH")) -> ĐẠT | M2: =IF(LEN(F2)=0,"ĐẠT",IF(SUMPRODUCT(--(BAI_DO_XE!$A$2:$A$1000=F2))>0,"ĐẠT","LỆCH")) -> ĐẠT | N2: =IF(IF(C2="Giám đốc điều hành",LEN(F2)=0,LEN(F2)>0),"ĐẠT","LỆCH") -> ĐẠT
A3: NV002 | B3: Trần Văn Hùng | C3: Quản lý bãi | D3: 0901000002 | E3: hung.tran@smartparking.vn | F3: BAI_Q1 | G3: =IF(LEN(F3)=0,"Toàn chuỗi",INDEX(BAI_DO_XE!$B$2:$B$1000,MATCH(F3,BAI_DO_XE!$A$2:$A$1000,0))) -> Bãi xe Lê Lai - Bến Thành | H3: =COUNTIF(TAI_KHOAN!$C$2:$C$1000,A3) -> 1 | I3: =IF(SUMPRODUCT(--(NHAN_VIEN!$A$2:$A$1000=A3))=1,"ĐẠT","LỆCH") -> ĐẠT | J3: =IF(AND(LEN(A3)=5,LEFT(A3,2)="NV",ISNUMBER(-MID(A3,3,3)),ISERROR(FIND(".",MID(A3,3,3)))),"ĐẠT","LỆCH") -> ĐẠT | K3: =IF(SUMPRODUCT(--(NHAN_VIEN!$D$2:$D$1000=D3))=1,"ĐẠT","LỆCH") -> ĐẠT | L3: =IF(LEN(E3)=0,"ĐẠT",IF(SUMPRODUCT(--(NHAN_VIEN!$E$2:$E$1000=E3))=1,"ĐẠT","LỆCH")) -> ĐẠT | M3: =IF(LEN(F3)=0,"ĐẠT",IF(SUMPRODUCT(--(BAI_DO_XE!$A$2:$A$1000=F3))>0,"ĐẠT","LỆCH")) -> ĐẠT | N3: =IF(IF(C3="Giám đốc điều hành",LEN(F3)=0,LEN(F3)>0),"ĐẠT","LỆCH") -> ĐẠT
A4: NV003 | B4: Lê Thị Bích Ngọc | C4: Quản lý bãi | D4: 0901000003 | E4: ngoc.le@smartparking.vn | F4: BAI_Q3 | G4: =IF(LEN(F4)=0,"Toàn chuỗi",INDEX(BAI_DO_XE!$B$2:$B$1000,MATCH(F4,BAI_DO_XE!$A$2:$A$1000,0))) -> Bãi xe Hai Bà Trưng | H4: =COUNTIF(TAI_KHOAN!$C$2:$C$1000,A4) -> 1 | I4: =IF(SUMPRODUCT(--(NHAN_VIEN!$A$2:$A$1000=A4))=1,"ĐẠT","LỆCH") -> ĐẠT | J4: =IF(AND(LEN(A4)=5,LEFT(A4,2)="NV",ISNUMBER(-MID(A4,3,3)),ISERROR(FIND(".",MID(A4,3,3)))),"ĐẠT","LỆCH") -> ĐẠT | K4: =IF(SUMPRODUCT(--(NHAN_VIEN!$D$2:$D$1000=D4))=1,"ĐẠT","LỆCH") -> ĐẠT | L4: =IF(LEN(E4)=0,"ĐẠT",IF(SUMPRODUCT(--(NHAN_VIEN!$E$2:$E$1000=E4))=1,"ĐẠT","LỆCH")) -> ĐẠT | M4: =IF(LEN(F4)=0,"ĐẠT",IF(SUMPRODUCT(--(BAI_DO_XE!$A$2:$A$1000=F4))>0,"ĐẠT","LỆCH")) -> ĐẠT | N4: =IF(IF(C4="Giám đốc điều hành",LEN(F4)=0,LEN(F4)>0),"ĐẠT","LỆCH") -> ĐẠT
A5: NV004 | B5: Hoàng Đình Nam | C5: Quản lý bãi | D5: 0901000004 | E5: nam.hoang@smartparking.vn | F5: BAI_BT | G5: =IF(LEN(F5)=0,"Toàn chuỗi",INDEX(BAI_DO_XE!$B$2:$B$1000,MATCH(F5,BAI_DO_XE!$A$2:$A$1000,0))) -> Bãi xe Landmark 81 | H5: =COUNTIF(TAI_KHOAN!$C$2:$C$1000,A5) -> 1 | I5: =IF(SUMPRODUCT(--(NHAN_VIEN!$A$2:$A$1000=A5))=1,"ĐẠT","LỆCH") -> ĐẠT | J5: =IF(AND(LEN(A5)=5,LEFT(A5,2)="NV",ISNUMBER(-MID(A5,3,3)),ISERROR(FIND(".",MID(A5,3,3)))),"ĐẠT","LỆCH") -> ĐẠT | K5: =IF(SUMPRODUCT(--(NHAN_VIEN!$D$2:$D$1000=D5))=1,"ĐẠT","LỆCH") -> ĐẠT | L5: =IF(LEN(E5)=0,"ĐẠT",IF(SUMPRODUCT(--(NHAN_VIEN!$E$2:$E$1000=E5))=1,"ĐẠT","LỆCH")) -> ĐẠT | M5: =IF(LEN(F5)=0,"ĐẠT",IF(SUMPRODUCT(--(BAI_DO_XE!$A$2:$A$1000=F5))>0,"ĐẠT","LỆCH")) -> ĐẠT | N5: =IF(IF(C5="Giám đốc điều hành",LEN(F5)=0,LEN(F5)>0),"ĐẠT","LỆCH") -> ĐẠT
A6: NV005 | B6: Phạm Văn Cường | C6: Bảo vệ | D6: 0901000005 | E6: cuong.pham@smartparking.vn | F6: BAI_Q1 | G6: =IF(LEN(F6)=0,"Toàn chuỗi",INDEX(BAI_DO_XE!$B$2:$B$1000,MATCH(F6,BAI_DO_XE!$A$2:$A$1000,0))) -> Bãi xe Lê Lai - Bến Thành | H6: =COUNTIF(TAI_KHOAN!$C$2:$C$1000,A6) -> 2 | I6: =IF(SUMPRODUCT(--(NHAN_VIEN!$A$2:$A$1000=A6))=1,"ĐẠT","LỆCH") -> ĐẠT | J6: =IF(AND(LEN(A6)=5,LEFT(A6,2)="NV",ISNUMBER(-MID(A6,3,3)),ISERROR(FIND(".",MID(A6,3,3)))),"ĐẠT","LỆCH") -> ĐẠT | K6: =IF(SUMPRODUCT(--(NHAN_VIEN!$D$2:$D$1000=D6))=1,"ĐẠT","LỆCH") -> ĐẠT | L6: =IF(LEN(E6)=0,"ĐẠT",IF(SUMPRODUCT(--(NHAN_VIEN!$E$2:$E$1000=E6))=1,"ĐẠT","LỆCH")) -> ĐẠT | M6: =IF(LEN(F6)=0,"ĐẠT",IF(SUMPRODUCT(--(BAI_DO_XE!$A$2:$A$1000=F6))>0,"ĐẠT","LỆCH")) -> ĐẠT | N6: =IF(IF(C6="Giám đốc điều hành",LEN(F6)=0,LEN(F6)>0),"ĐẠT","LỆCH") -> ĐẠT
A7: NV006 | B7: Đặng Minh Tuấn | C7: Bảo vệ | D7: 0901000006 | E7: tuan.dang@smartparking.vn | F7: BAI_Q3 | G7: =IF(LEN(F7)=0,"Toàn chuỗi",INDEX(BAI_DO_XE!$B$2:$B$1000,MATCH(F7,BAI_DO_XE!$A$2:$A$1000,0))) -> Bãi xe Hai Bà Trưng | H7: =COUNTIF(TAI_KHOAN!$C$2:$C$1000,A7) -> 1 | I7: =IF(SUMPRODUCT(--(NHAN_VIEN!$A$2:$A$1000=A7))=1,"ĐẠT","LỆCH") -> ĐẠT | J7: =IF(AND(LEN(A7)=5,LEFT(A7,2)="NV",ISNUMBER(-MID(A7,3,3)),ISERROR(FIND(".",MID(A7,3,3)))),"ĐẠT","LỆCH") -> ĐẠT | K7: =IF(SUMPRODUCT(--(NHAN_VIEN!$D$2:$D$1000=D7))=1,"ĐẠT","LỆCH") -> ĐẠT | L7: =IF(LEN(E7)=0,"ĐẠT",IF(SUMPRODUCT(--(NHAN_VIEN!$E$2:$E$1000=E7))=1,"ĐẠT","LỆCH")) -> ĐẠT | M7: =IF(LEN(F7)=0,"ĐẠT",IF(SUMPRODUCT(--(BAI_DO_XE!$A$2:$A$1000=F7))>0,"ĐẠT","LỆCH")) -> ĐẠT | N7: =IF(IF(C7="Giám đốc điều hành",LEN(F7)=0,LEN(F7)>0),"ĐẠT","LỆCH") -> ĐẠT
A8: NV007 | B8: Vũ Đức Thắng | C8: Bảo vệ | D8: 0901000007 | E8: thang.vu@smartparking.vn | F8: BAI_BT | G8: =IF(LEN(F8)=0,"Toàn chuỗi",INDEX(BAI_DO_XE!$B$2:$B$1000,MATCH(F8,BAI_DO_XE!$A$2:$A$1000,0))) -> Bãi xe Landmark 81 | H8: =COUNTIF(TAI_KHOAN!$C$2:$C$1000,A8) -> 1 | I8: =IF(SUMPRODUCT(--(NHAN_VIEN!$A$2:$A$1000=A8))=1,"ĐẠT","LỆCH") -> ĐẠT | J8: =IF(AND(LEN(A8)=5,LEFT(A8,2)="NV",ISNUMBER(-MID(A8,3,3)),ISERROR(FIND(".",MID(A8,3,3)))),"ĐẠT","LỆCH") -> ĐẠT | K8: =IF(SUMPRODUCT(--(NHAN_VIEN!$D$2:$D$1000=D8))=1,"ĐẠT","LỆCH") -> ĐẠT | L8: =IF(LEN(E8)=0,"ĐẠT",IF(SUMPRODUCT(--(NHAN_VIEN!$E$2:$E$1000=E8))=1,"ĐẠT","LỆCH")) -> ĐẠT | M8: =IF(LEN(F8)=0,"ĐẠT",IF(SUMPRODUCT(--(BAI_DO_XE!$A$2:$A$1000=F8))>0,"ĐẠT","LỆCH")) -> ĐẠT | N8: =IF(IF(C8="Giám đốc điều hành",LEN(F8)=0,LEN(F8)>0),"ĐẠT","LỆCH") -> ĐẠT
A9: NV008 | B9: Huỳnh Quốc Bảo | C9: Quản lý bãi | D9: 0901000008 | E9: bao.huynh@smartparking.vn | F9: BAI_TB | G9: =IF(LEN(F9)=0,"Toàn chuỗi",INDEX(BAI_DO_XE!$B$2:$B$1000,MATCH(F9,BAI_DO_XE!$A$2:$A$1000,0))) -> Bãi xe TCP Park - Sân bay Tân Sơn Nhất | H9: =COUNTIF(TAI_KHOAN!$C$2:$C$1000,A9) -> 1 | I9: =IF(SUMPRODUCT(--(NHAN_VIEN!$A$2:$A$1000=A9))=1,"ĐẠT","LỆCH") -> ĐẠT | J9: =IF(AND(LEN(A9)=5,LEFT(A9,2)="NV",ISNUMBER(-MID(A9,3,3)),ISERROR(FIND(".",MID(A9,3,3)))),"ĐẠT","LỆCH") -> ĐẠT | K9: =IF(SUMPRODUCT(--(NHAN_VIEN!$D$2:$D$1000=D9))=1,"ĐẠT","LỆCH") -> ĐẠT | L9: =IF(LEN(E9)=0,"ĐẠT",IF(SUMPRODUCT(--(NHAN_VIEN!$E$2:$E$1000=E9))=1,"ĐẠT","LỆCH")) -> ĐẠT | M9: =IF(LEN(F9)=0,"ĐẠT",IF(SUMPRODUCT(--(BAI_DO_XE!$A$2:$A$1000=F9))>0,"ĐẠT","LỆCH")) -> ĐẠT | N9: =IF(IF(C9="Giám đốc điều hành",LEN(F9)=0,LEN(F9)>0),"ĐẠT","LỆCH") -> ĐẠT
A10: NV009 | B10: Ngô Thị Thanh Hà | C10: Quản lý bãi | D10: 0901000009 | E10: ha.ngo@smartparking.vn | F10: BAI_Q7 | G10: =IF(LEN(F10)=0,"Toàn chuỗi",INDEX(BAI_DO_XE!$B$2:$B$1000,MATCH(F10,BAI_DO_XE!$A$2:$A$1000,0))) -> Bãi xe SC VivoCity | H10: =COUNTIF(TAI_KHOAN!$C$2:$C$1000,A10) -> 1 | I10: =IF(SUMPRODUCT(--(NHAN_VIEN!$A$2:$A$1000=A10))=1,"ĐẠT","LỆCH") -> ĐẠT | J10: =IF(AND(LEN(A10)=5,LEFT(A10,2)="NV",ISNUMBER(-MID(A10,3,3)),ISERROR(FIND(".",MID(A10,3,3)))),"ĐẠT","LỆCH") -> ĐẠT | K10: =IF(SUMPRODUCT(--(NHAN_VIEN!$D$2:$D$1000=D10))=1,"ĐẠT","LỆCH") -> ĐẠT | L10: =IF(LEN(E10)=0,"ĐẠT",IF(SUMPRODUCT(--(NHAN_VIEN!$E$2:$E$1000=E10))=1,"ĐẠT","LỆCH")) -> ĐẠT | M10: =IF(LEN(F10)=0,"ĐẠT",IF(SUMPRODUCT(--(BAI_DO_XE!$A$2:$A$1000=F10))>0,"ĐẠT","LỆCH")) -> ĐẠT | N10: =IF(IF(C10="Giám đốc điều hành",LEN(F10)=0,LEN(F10)>0),"ĐẠT","LỆCH") -> ĐẠT
A11: NV010 | B11: Trương Văn Lộc | C11: Bảo vệ | D11: 0901000010 | E11: loc.truong@smartparking.vn | F11: BAI_TB | G11: =IF(LEN(F11)=0,"Toàn chuỗi",INDEX(BAI_DO_XE!$B$2:$B$1000,MATCH(F11,BAI_DO_XE!$A$2:$A$1000,0))) -> Bãi xe TCP Park - Sân bay Tân Sơn Nhất | H11: =COUNTIF(TAI_KHOAN!$C$2:$C$1000,A11) -> 1 | I11: =IF(SUMPRODUCT(--(NHAN_VIEN!$A$2:$A$1000=A11))=1,"ĐẠT","LỆCH") -> ĐẠT | J11: =IF(AND(LEN(A11)=5,LEFT(A11,2)="NV",ISNUMBER(-MID(A11,3,3)),ISERROR(FIND(".",MID(A11,3,3)))),"ĐẠT","LỆCH") -> ĐẠT | K11: =IF(SUMPRODUCT(--(NHAN_VIEN!$D$2:$D$1000=D11))=1,"ĐẠT","LỆCH") -> ĐẠT | L11: =IF(LEN(E11)=0,"ĐẠT",IF(SUMPRODUCT(--(NHAN_VIEN!$E$2:$E$1000=E11))=1,"ĐẠT","LỆCH")) -> ĐẠT | M11: =IF(LEN(F11)=0,"ĐẠT",IF(SUMPRODUCT(--(BAI_DO_XE!$A$2:$A$1000=F11))>0,"ĐẠT","LỆCH")) -> ĐẠT | N11: =IF(IF(C11="Giám đốc điều hành",LEN(F11)=0,LEN(F11)>0),"ĐẠT","LỆCH") -> ĐẠT
A12: NV011 | B12: Bùi Thành Đạt | C12: Bảo vệ | D12: 0901000011 | E12: dat.bui@smartparking.vn | F12: BAI_Q7 | G12: =IF(LEN(F12)=0,"Toàn chuỗi",INDEX(BAI_DO_XE!$B$2:$B$1000,MATCH(F12,BAI_DO_XE!$A$2:$A$1000,0))) -> Bãi xe SC VivoCity | H12: =COUNTIF(TAI_KHOAN!$C$2:$C$1000,A12) -> 1 | I12: =IF(SUMPRODUCT(--(NHAN_VIEN!$A$2:$A$1000=A12))=1,"ĐẠT","LỆCH") -> ĐẠT | J12: =IF(AND(LEN(A12)=5,LEFT(A12,2)="NV",ISNUMBER(-MID(A12,3,3)),ISERROR(FIND(".",MID(A12,3,3)))),"ĐẠT","LỆCH") -> ĐẠT | K12: =IF(SUMPRODUCT(--(NHAN_VIEN!$D$2:$D$1000=D12))=1,"ĐẠT","LỆCH") -> ĐẠT | L12: =IF(LEN(E12)=0,"ĐẠT",IF(SUMPRODUCT(--(NHAN_VIEN!$E$2:$E$1000=E12))=1,"ĐẠT","LỆCH")) -> ĐẠT | M12: =IF(LEN(F12)=0,"ĐẠT",IF(SUMPRODUCT(--(BAI_DO_XE!$A$2:$A$1000=F12))>0,"ĐẠT","LỆCH")) -> ĐẠT | N12: =IF(IF(C12="Giám đốc điều hành",LEN(F12)=0,LEN(F12)>0),"ĐẠT","LỆCH") -> ĐẠT

Sheet TAI_KHOAN
A1: TenDangNhap | B1: MatKhauHash | C1: MaNV | D1: TrangThai | E1: MatKhauMau | F1: HoTen | G1: ChucVu | H1: KetQuaDangNhap | I1: KT_PK | J1: KT_FK_MaNV | K1: KT_DoDaiHash
A2: admin | B2: A36AEF5A11C4073FBE60314FC9DF530A9D5F986533594D1F5190742FF9E0E408 | C2: NV001 | D2: Hoạt động | E2: Admin@2026 | F2: =INDEX(NHAN_VIEN!$B$2:$B$1000,MATCH(C2,NHAN_VIEN!$A$2:$A$1000,0)) -> Nguyễn Hữu Trí | G2: =INDEX(NHAN_VIEN!$C$2:$C$1000,MATCH(C2,NHAN_VIEN!$A$2:$A$1000,0)) -> Giám đốc điều hành | H2: =IF(D2="Hoạt động","Đăng nhập được (nếu đúng mật khẩu)","CHẶN 50021 - Tài khoản bị khóa") -> Đăng nhập được (nếu đúng mật khẩu) | I2: =IF(SUMPRODUCT(--(TAI_KHOAN!$A$2:$A$1000=A2))=1,"ĐẠT","LỆCH") -> ĐẠT | J2: =IF(SUMPRODUCT(--(NHAN_VIEN!$A$2:$A$1000=C2))>0,"ĐẠT","LỆCH") -> ĐẠT | K2: =IF(LEN(B2)=64,"ĐẠT","LỆCH") -> ĐẠT
A3: quanly_q1 | B3: 8D969EEF6ECAD3C29A3A629280E686CF0C3F5D5A86AFF3CA12020C923ADC6C92 | C3: NV002 | D3: Hoạt động | E3: 123456 | F3: =INDEX(NHAN_VIEN!$B$2:$B$1000,MATCH(C3,NHAN_VIEN!$A$2:$A$1000,0)) -> Trần Văn Hùng | G3: =INDEX(NHAN_VIEN!$C$2:$C$1000,MATCH(C3,NHAN_VIEN!$A$2:$A$1000,0)) -> Quản lý bãi | H3: =IF(D3="Hoạt động","Đăng nhập được (nếu đúng mật khẩu)","CHẶN 50021 - Tài khoản bị khóa") -> Đăng nhập được (nếu đúng mật khẩu) | I3: =IF(SUMPRODUCT(--(TAI_KHOAN!$A$2:$A$1000=A3))=1,"ĐẠT","LỆCH") -> ĐẠT | J3: =IF(SUMPRODUCT(--(NHAN_VIEN!$A$2:$A$1000=C3))>0,"ĐẠT","LỆCH") -> ĐẠT | K3: =IF(LEN(B3)=64,"ĐẠT","LỆCH") -> ĐẠT
A4: quanly_q3 | B4: 8D969EEF6ECAD3C29A3A629280E686CF0C3F5D5A86AFF3CA12020C923ADC6C92 | C4: NV003 | D4: Hoạt động | E4: 123456 | F4: =INDEX(NHAN_VIEN!$B$2:$B$1000,MATCH(C4,NHAN_VIEN!$A$2:$A$1000,0)) -> Lê Thị Bích Ngọc | G4: =INDEX(NHAN_VIEN!$C$2:$C$1000,MATCH(C4,NHAN_VIEN!$A$2:$A$1000,0)) -> Quản lý bãi | H4: =IF(D4="Hoạt động","Đăng nhập được (nếu đúng mật khẩu)","CHẶN 50021 - Tài khoản bị khóa") -> Đăng nhập được (nếu đúng mật khẩu) | I4: =IF(SUMPRODUCT(--(TAI_KHOAN!$A$2:$A$1000=A4))=1,"ĐẠT","LỆCH") -> ĐẠT | J4: =IF(SUMPRODUCT(--(NHAN_VIEN!$A$2:$A$1000=C4))>0,"ĐẠT","LỆCH") -> ĐẠT | K4: =IF(LEN(B4)=64,"ĐẠT","LỆCH") -> ĐẠT
A5: quanly_bt | B5: 8D969EEF6ECAD3C29A3A629280E686CF0C3F5D5A86AFF3CA12020C923ADC6C92 | C5: NV004 | D5: Hoạt động | E5: 123456 | F5: =INDEX(NHAN_VIEN!$B$2:$B$1000,MATCH(C5,NHAN_VIEN!$A$2:$A$1000,0)) -> Hoàng Đình Nam | G5: =INDEX(NHAN_VIEN!$C$2:$C$1000,MATCH(C5,NHAN_VIEN!$A$2:$A$1000,0)) -> Quản lý bãi | H5: =IF(D5="Hoạt động","Đăng nhập được (nếu đúng mật khẩu)","CHẶN 50021 - Tài khoản bị khóa") -> Đăng nhập được (nếu đúng mật khẩu) | I5: =IF(SUMPRODUCT(--(TAI_KHOAN!$A$2:$A$1000=A5))=1,"ĐẠT","LỆCH") -> ĐẠT | J5: =IF(SUMPRODUCT(--(NHAN_VIEN!$A$2:$A$1000=C5))>0,"ĐẠT","LỆCH") -> ĐẠT | K5: =IF(LEN(B5)=64,"ĐẠT","LỆCH") -> ĐẠT
A6: baove_khoa | B6: 8D969EEF6ECAD3C29A3A629280E686CF0C3F5D5A86AFF3CA12020C923ADC6C92 | C6: NV005 | D6: Bị khóa | E6: 123456 | F6: =INDEX(NHAN_VIEN!$B$2:$B$1000,MATCH(C6,NHAN_VIEN!$A$2:$A$1000,0)) -> Phạm Văn Cường | G6: =INDEX(NHAN_VIEN!$C$2:$C$1000,MATCH(C6,NHAN_VIEN!$A$2:$A$1000,0)) -> Bảo vệ | H6: =IF(D6="Hoạt động","Đăng nhập được (nếu đúng mật khẩu)","CHẶN 50021 - Tài khoản bị khóa") -> CHẶN 50021 - Tài khoản bị khóa | I6: =IF(SUMPRODUCT(--(TAI_KHOAN!$A$2:$A$1000=A6))=1,"ĐẠT","LỆCH") -> ĐẠT | J6: =IF(SUMPRODUCT(--(NHAN_VIEN!$A$2:$A$1000=C6))>0,"ĐẠT","LỆCH") -> ĐẠT | K6: =IF(LEN(B6)=64,"ĐẠT","LỆCH") -> ĐẠT
A7: baove_q1 | B7: 8D969EEF6ECAD3C29A3A629280E686CF0C3F5D5A86AFF3CA12020C923ADC6C92 | C7: NV005 | D7: Hoạt động | E7: 123456 | F7: =INDEX(NHAN_VIEN!$B$2:$B$1000,MATCH(C7,NHAN_VIEN!$A$2:$A$1000,0)) -> Phạm Văn Cường | G7: =INDEX(NHAN_VIEN!$C$2:$C$1000,MATCH(C7,NHAN_VIEN!$A$2:$A$1000,0)) -> Bảo vệ | H7: =IF(D7="Hoạt động","Đăng nhập được (nếu đúng mật khẩu)","CHẶN 50021 - Tài khoản bị khóa") -> Đăng nhập được (nếu đúng mật khẩu) | I7: =IF(SUMPRODUCT(--(TAI_KHOAN!$A$2:$A$1000=A7))=1,"ĐẠT","LỆCH") -> ĐẠT | J7: =IF(SUMPRODUCT(--(NHAN_VIEN!$A$2:$A$1000=C7))>0,"ĐẠT","LỆCH") -> ĐẠT | K7: =IF(LEN(B7)=64,"ĐẠT","LỆCH") -> ĐẠT
A8: baove_q3 | B8: 8D969EEF6ECAD3C29A3A629280E686CF0C3F5D5A86AFF3CA12020C923ADC6C92 | C8: NV006 | D8: Hoạt động | E8: 123456 | F8: =INDEX(NHAN_VIEN!$B$2:$B$1000,MATCH(C8,NHAN_VIEN!$A$2:$A$1000,0)) -> Đặng Minh Tuấn | G8: =INDEX(NHAN_VIEN!$C$2:$C$1000,MATCH(C8,NHAN_VIEN!$A$2:$A$1000,0)) -> Bảo vệ | H8: =IF(D8="Hoạt động","Đăng nhập được (nếu đúng mật khẩu)","CHẶN 50021 - Tài khoản bị khóa") -> Đăng nhập được (nếu đúng mật khẩu) | I8: =IF(SUMPRODUCT(--(TAI_KHOAN!$A$2:$A$1000=A8))=1,"ĐẠT","LỆCH") -> ĐẠT | J8: =IF(SUMPRODUCT(--(NHAN_VIEN!$A$2:$A$1000=C8))>0,"ĐẠT","LỆCH") -> ĐẠT | K8: =IF(LEN(B8)=64,"ĐẠT","LỆCH") -> ĐẠT
A9: baove_bt | B9: 8D969EEF6ECAD3C29A3A629280E686CF0C3F5D5A86AFF3CA12020C923ADC6C92 | C9: NV007 | D9: Hoạt động | E9: 123456 | F9: =INDEX(NHAN_VIEN!$B$2:$B$1000,MATCH(C9,NHAN_VIEN!$A$2:$A$1000,0)) -> Vũ Đức Thắng | G9: =INDEX(NHAN_VIEN!$C$2:$C$1000,MATCH(C9,NHAN_VIEN!$A$2:$A$1000,0)) -> Bảo vệ | H9: =IF(D9="Hoạt động","Đăng nhập được (nếu đúng mật khẩu)","CHẶN 50021 - Tài khoản bị khóa") -> Đăng nhập được (nếu đúng mật khẩu) | I9: =IF(SUMPRODUCT(--(TAI_KHOAN!$A$2:$A$1000=A9))=1,"ĐẠT","LỆCH") -> ĐẠT | J9: =IF(SUMPRODUCT(--(NHAN_VIEN!$A$2:$A$1000=C9))>0,"ĐẠT","LỆCH") -> ĐẠT | K9: =IF(LEN(B9)=64,"ĐẠT","LỆCH") -> ĐẠT
A10: quanly_tb | B10: 8D969EEF6ECAD3C29A3A629280E686CF0C3F5D5A86AFF3CA12020C923ADC6C92 | C10: NV008 | D10: Hoạt động | E10: 123456 | F10: =INDEX(NHAN_VIEN!$B$2:$B$1000,MATCH(C10,NHAN_VIEN!$A$2:$A$1000,0)) -> Huỳnh Quốc Bảo | G10: =INDEX(NHAN_VIEN!$C$2:$C$1000,MATCH(C10,NHAN_VIEN!$A$2:$A$1000,0)) -> Quản lý bãi | H10: =IF(D10="Hoạt động","Đăng nhập được (nếu đúng mật khẩu)","CHẶN 50021 - Tài khoản bị khóa") -> Đăng nhập được (nếu đúng mật khẩu) | I10: =IF(SUMPRODUCT(--(TAI_KHOAN!$A$2:$A$1000=A10))=1,"ĐẠT","LỆCH") -> ĐẠT | J10: =IF(SUMPRODUCT(--(NHAN_VIEN!$A$2:$A$1000=C10))>0,"ĐẠT","LỆCH") -> ĐẠT | K10: =IF(LEN(B10)=64,"ĐẠT","LỆCH") -> ĐẠT
A11: quanly_q7 | B11: 8D969EEF6ECAD3C29A3A629280E686CF0C3F5D5A86AFF3CA12020C923ADC6C92 | C11: NV009 | D11: Hoạt động | E11: 123456 | F11: =INDEX(NHAN_VIEN!$B$2:$B$1000,MATCH(C11,NHAN_VIEN!$A$2:$A$1000,0)) -> Ngô Thị Thanh Hà | G11: =INDEX(NHAN_VIEN!$C$2:$C$1000,MATCH(C11,NHAN_VIEN!$A$2:$A$1000,0)) -> Quản lý bãi | H11: =IF(D11="Hoạt động","Đăng nhập được (nếu đúng mật khẩu)","CHẶN 50021 - Tài khoản bị khóa") -> Đăng nhập được (nếu đúng mật khẩu) | I11: =IF(SUMPRODUCT(--(TAI_KHOAN!$A$2:$A$1000=A11))=1,"ĐẠT","LỆCH") -> ĐẠT | J11: =IF(SUMPRODUCT(--(NHAN_VIEN!$A$2:$A$1000=C11))>0,"ĐẠT","LỆCH") -> ĐẠT | K11: =IF(LEN(B11)=64,"ĐẠT","LỆCH") -> ĐẠT
A12: baove_tb | B12: 8D969EEF6ECAD3C29A3A629280E686CF0C3F5D5A86AFF3CA12020C923ADC6C92 | C12: NV010 | D12: Hoạt động | E12: 123456 | F12: =INDEX(NHAN_VIEN!$B$2:$B$1000,MATCH(C12,NHAN_VIEN!$A$2:$A$1000,0)) -> Trương Văn Lộc | G12: =INDEX(NHAN_VIEN!$C$2:$C$1000,MATCH(C12,NHAN_VIEN!$A$2:$A$1000,0)) -> Bảo vệ | H12: =IF(D12="Hoạt động","Đăng nhập được (nếu đúng mật khẩu)","CHẶN 50021 - Tài khoản bị khóa") -> Đăng nhập được (nếu đúng mật khẩu) | I12: =IF(SUMPRODUCT(--(TAI_KHOAN!$A$2:$A$1000=A12))=1,"ĐẠT","LỆCH") -> ĐẠT | J12: =IF(SUMPRODUCT(--(NHAN_VIEN!$A$2:$A$1000=C12))>0,"ĐẠT","LỆCH") -> ĐẠT | K12: =IF(LEN(B12)=64,"ĐẠT","LỆCH") -> ĐẠT
A13: baove_q7 | B13: 8D969EEF6ECAD3C29A3A629280E686CF0C3F5D5A86AFF3CA12020C923ADC6C92 | C13: NV011 | D13: Hoạt động | E13: 123456 | F13: =INDEX(NHAN_VIEN!$B$2:$B$1000,MATCH(C13,NHAN_VIEN!$A$2:$A$1000,0)) -> Bùi Thành Đạt | G13: =INDEX(NHAN_VIEN!$C$2:$C$1000,MATCH(C13,NHAN_VIEN!$A$2:$A$1000,0)) -> Bảo vệ | H13: =IF(D13="Hoạt động","Đăng nhập được (nếu đúng mật khẩu)","CHẶN 50021 - Tài khoản bị khóa") -> Đăng nhập được (nếu đúng mật khẩu) | I13: =IF(SUMPRODUCT(--(TAI_KHOAN!$A$2:$A$1000=A13))=1,"ĐẠT","LỆCH") -> ĐẠT | J13: =IF(SUMPRODUCT(--(NHAN_VIEN!$A$2:$A$1000=C13))>0,"ĐẠT","LỆCH") -> ĐẠT | K13: =IF(LEN(B13)=64,"ĐẠT","LỆCH") -> ĐẠT

Sheet LOAI_XE
A1: MaLoaiXe | B1: MaBai | C1: TenLoai | D1: DonGiaGio | E1: GiaVeThang | F1: TenBai | G1: SoO | H1: SoOTrong | I1: KT_PK | J1: KT_FK_MaBai | K1: KT_GiaDuong
A2: OT | B2: BAI_BT | C2: Ô tô 4-7 chỗ | D2: 30000 | E2: 2200000 | F2: =INDEX(BAI_DO_XE!$B$2:$B$1000,MATCH(B2,BAI_DO_XE!$A$2:$A$1000,0)) -> Bãi xe Landmark 81 | G2: =COUNTIFS(VI_TRI_DO!$D$2:$D$1000,A2,VI_TRI_DO!$E$2:$E$1000,B2) -> 4 | H2: =COUNTIFS(VI_TRI_DO!$D$2:$D$1000,A2,VI_TRI_DO!$E$2:$E$1000,B2,VI_TRI_DO!$C$2:$C$1000,"Trống") -> 3 | I2: =IF(SUMPRODUCT((LOAI_XE!$A$2:$A$1000=A2)*(LOAI_XE!$B$2:$B$1000=B2))=1,"ĐẠT","LỆCH") -> ĐẠT | J2: =IF(SUMPRODUCT(--(BAI_DO_XE!$A$2:$A$1000=B2))>0,"ĐẠT","LỆCH") -> ĐẠT | K2: =IF(AND(D2>0,E2>0),"ĐẠT","LỆCH") -> ĐẠT
A3: XD | B3: BAI_BT | C3: Xe đạp / Xe điện | D3: 4000 | E3: 90000 | F3: =INDEX(BAI_DO_XE!$B$2:$B$1000,MATCH(B3,BAI_DO_XE!$A$2:$A$1000,0)) -> Bãi xe Landmark 81 | G3: =COUNTIFS(VI_TRI_DO!$D$2:$D$1000,A3,VI_TRI_DO!$E$2:$E$1000,B3) -> 2 | H3: =COUNTIFS(VI_TRI_DO!$D$2:$D$1000,A3,VI_TRI_DO!$E$2:$E$1000,B3,VI_TRI_DO!$C$2:$C$1000,"Trống") -> 2 | I3: =IF(SUMPRODUCT((LOAI_XE!$A$2:$A$1000=A3)*(LOAI_XE!$B$2:$B$1000=B3))=1,"ĐẠT","LỆCH") -> ĐẠT | J3: =IF(SUMPRODUCT(--(BAI_DO_XE!$A$2:$A$1000=B3))>0,"ĐẠT","LỆCH") -> ĐẠT | K3: =IF(AND(D3>0,E3>0),"ĐẠT","LỆCH") -> ĐẠT
A4: XM | B4: BAI_BT | C4: Xe máy | D4: 7000 | E4: 200000 | F4: =INDEX(BAI_DO_XE!$B$2:$B$1000,MATCH(B4,BAI_DO_XE!$A$2:$A$1000,0)) -> Bãi xe Landmark 81 | G4: =COUNTIFS(VI_TRI_DO!$D$2:$D$1000,A4,VI_TRI_DO!$E$2:$E$1000,B4) -> 6 | H4: =COUNTIFS(VI_TRI_DO!$D$2:$D$1000,A4,VI_TRI_DO!$E$2:$E$1000,B4,VI_TRI_DO!$C$2:$C$1000,"Trống") -> 6 | I4: =IF(SUMPRODUCT((LOAI_XE!$A$2:$A$1000=A4)*(LOAI_XE!$B$2:$B$1000=B4))=1,"ĐẠT","LỆCH") -> ĐẠT | J4: =IF(SUMPRODUCT(--(BAI_DO_XE!$A$2:$A$1000=B4))>0,"ĐẠT","LỆCH") -> ĐẠT | K4: =IF(AND(D4>0,E4>0),"ĐẠT","LỆCH") -> ĐẠT
A5: OT | B5: BAI_Q1 | C5: Ô tô 4-7 chỗ | D5: 25000 | E5: 1800000 | F5: =INDEX(BAI_DO_XE!$B$2:$B$1000,MATCH(B5,BAI_DO_XE!$A$2:$A$1000,0)) -> Bãi xe Lê Lai - Bến Thành | G5: =COUNTIFS(VI_TRI_DO!$D$2:$D$1000,A5,VI_TRI_DO!$E$2:$E$1000,B5) -> 4 | H5: =COUNTIFS(VI_TRI_DO!$D$2:$D$1000,A5,VI_TRI_DO!$E$2:$E$1000,B5,VI_TRI_DO!$C$2:$C$1000,"Trống") -> 4 | I5: =IF(SUMPRODUCT((LOAI_XE!$A$2:$A$1000=A5)*(LOAI_XE!$B$2:$B$1000=B5))=1,"ĐẠT","LỆCH") -> ĐẠT | J5: =IF(SUMPRODUCT(--(BAI_DO_XE!$A$2:$A$1000=B5))>0,"ĐẠT","LỆCH") -> ĐẠT | K5: =IF(AND(D5>0,E5>0),"ĐẠT","LỆCH") -> ĐẠT
A6: XD | B6: BAI_Q1 | C6: Xe đạp / Xe điện | D6: 3000 | E6: 80000 | F6: =INDEX(BAI_DO_XE!$B$2:$B$1000,MATCH(B6,BAI_DO_XE!$A$2:$A$1000,0)) -> Bãi xe Lê Lai - Bến Thành | G6: =COUNTIFS(VI_TRI_DO!$D$2:$D$1000,A6,VI_TRI_DO!$E$2:$E$1000,B6) -> 2 | H6: =COUNTIFS(VI_TRI_DO!$D$2:$D$1000,A6,VI_TRI_DO!$E$2:$E$1000,B6,VI_TRI_DO!$C$2:$C$1000,"Trống") -> 2 | I6: =IF(SUMPRODUCT((LOAI_XE!$A$2:$A$1000=A6)*(LOAI_XE!$B$2:$B$1000=B6))=1,"ĐẠT","LỆCH") -> ĐẠT | J6: =IF(SUMPRODUCT(--(BAI_DO_XE!$A$2:$A$1000=B6))>0,"ĐẠT","LỆCH") -> ĐẠT | K6: =IF(AND(D6>0,E6>0),"ĐẠT","LỆCH") -> ĐẠT
A7: XM | B7: BAI_Q1 | C7: Xe máy | D7: 6000 | E7: 180000 | F7: =INDEX(BAI_DO_XE!$B$2:$B$1000,MATCH(B7,BAI_DO_XE!$A$2:$A$1000,0)) -> Bãi xe Lê Lai - Bến Thành | G7: =COUNTIFS(VI_TRI_DO!$D$2:$D$1000,A7,VI_TRI_DO!$E$2:$E$1000,B7) -> 6 | H7: =COUNTIFS(VI_TRI_DO!$D$2:$D$1000,A7,VI_TRI_DO!$E$2:$E$1000,B7,VI_TRI_DO!$C$2:$C$1000,"Trống") -> 4 | I7: =IF(SUMPRODUCT((LOAI_XE!$A$2:$A$1000=A7)*(LOAI_XE!$B$2:$B$1000=B7))=1,"ĐẠT","LỆCH") -> ĐẠT | J7: =IF(SUMPRODUCT(--(BAI_DO_XE!$A$2:$A$1000=B7))>0,"ĐẠT","LỆCH") -> ĐẠT | K7: =IF(AND(D7>0,E7>0),"ĐẠT","LỆCH") -> ĐẠT
A8: OT | B8: BAI_Q3 | C8: Ô tô 4-7 chỗ | D8: 20000 | E8: 1500000 | F8: =INDEX(BAI_DO_XE!$B$2:$B$1000,MATCH(B8,BAI_DO_XE!$A$2:$A$1000,0)) -> Bãi xe Hai Bà Trưng | G8: =COUNTIFS(VI_TRI_DO!$D$2:$D$1000,A8,VI_TRI_DO!$E$2:$E$1000,B8) -> 3 | H8: =COUNTIFS(VI_TRI_DO!$D$2:$D$1000,A8,VI_TRI_DO!$E$2:$E$1000,B8,VI_TRI_DO!$C$2:$C$1000,"Trống") -> 3 | I8: =IF(SUMPRODUCT((LOAI_XE!$A$2:$A$1000=A8)*(LOAI_XE!$B$2:$B$1000=B8))=1,"ĐẠT","LỆCH") -> ĐẠT | J8: =IF(SUMPRODUCT(--(BAI_DO_XE!$A$2:$A$1000=B8))>0,"ĐẠT","LỆCH") -> ĐẠT | K8: =IF(AND(D8>0,E8>0),"ĐẠT","LỆCH") -> ĐẠT
A9: XD | B9: BAI_Q3 | C9: Xe đạp / Xe điện | D9: 2000 | E9: 60000 | F9: =INDEX(BAI_DO_XE!$B$2:$B$1000,MATCH(B9,BAI_DO_XE!$A$2:$A$1000,0)) -> Bãi xe Hai Bà Trưng | G9: =COUNTIFS(VI_TRI_DO!$D$2:$D$1000,A9,VI_TRI_DO!$E$2:$E$1000,B9) -> 2 | H9: =COUNTIFS(VI_TRI_DO!$D$2:$D$1000,A9,VI_TRI_DO!$E$2:$E$1000,B9,VI_TRI_DO!$C$2:$C$1000,"Trống") -> 2 | I9: =IF(SUMPRODUCT((LOAI_XE!$A$2:$A$1000=A9)*(LOAI_XE!$B$2:$B$1000=B9))=1,"ĐẠT","LỆCH") -> ĐẠT | J9: =IF(SUMPRODUCT(--(BAI_DO_XE!$A$2:$A$1000=B9))>0,"ĐẠT","LỆCH") -> ĐẠT | K9: =IF(AND(D9>0,E9>0),"ĐẠT","LỆCH") -> ĐẠT
A10: XM | B10: BAI_Q3 | C10: Xe máy | D10: 5000 | E10: 150000 | F10: =INDEX(BAI_DO_XE!$B$2:$B$1000,MATCH(B10,BAI_DO_XE!$A$2:$A$1000,0)) -> Bãi xe Hai Bà Trưng | G10: =COUNTIFS(VI_TRI_DO!$D$2:$D$1000,A10,VI_TRI_DO!$E$2:$E$1000,B10) -> 5 | H10: =COUNTIFS(VI_TRI_DO!$D$2:$D$1000,A10,VI_TRI_DO!$E$2:$E$1000,B10,VI_TRI_DO!$C$2:$C$1000,"Trống") -> 4 | I10: =IF(SUMPRODUCT((LOAI_XE!$A$2:$A$1000=A10)*(LOAI_XE!$B$2:$B$1000=B10))=1,"ĐẠT","LỆCH") -> ĐẠT | J10: =IF(SUMPRODUCT(--(BAI_DO_XE!$A$2:$A$1000=B10))>0,"ĐẠT","LỆCH") -> ĐẠT | K10: =IF(AND(D10>0,E10>0),"ĐẠT","LỆCH") -> ĐẠT
A11: OT | B11: BAI_Q7 | C11: Ô tô 4-7 chỗ | D11: 20000 | E11: 1700000 | F11: =INDEX(BAI_DO_XE!$B$2:$B$1000,MATCH(B11,BAI_DO_XE!$A$2:$A$1000,0)) -> Bãi xe SC VivoCity | G11: =COUNTIFS(VI_TRI_DO!$D$2:$D$1000,A11,VI_TRI_DO!$E$2:$E$1000,B11) -> 5 | H11: =COUNTIFS(VI_TRI_DO!$D$2:$D$1000,A11,VI_TRI_DO!$E$2:$E$1000,B11,VI_TRI_DO!$C$2:$C$1000,"Trống") -> 4 | I11: =IF(SUMPRODUCT((LOAI_XE!$A$2:$A$1000=A11)*(LOAI_XE!$B$2:$B$1000=B11))=1,"ĐẠT","LỆCH") -> ĐẠT | J11: =IF(SUMPRODUCT(--(BAI_DO_XE!$A$2:$A$1000=B11))>0,"ĐẠT","LỆCH") -> ĐẠT | K11: =IF(AND(D11>0,E11>0),"ĐẠT","LỆCH") -> ĐẠT
A12: XD | B12: BAI_Q7 | C12: Xe đạp / Xe điện | D12: 2000 | E12: 70000 | F12: =INDEX(BAI_DO_XE!$B$2:$B$1000,MATCH(B12,BAI_DO_XE!$A$2:$A$1000,0)) -> Bãi xe SC VivoCity | G12: =COUNTIFS(VI_TRI_DO!$D$2:$D$1000,A12,VI_TRI_DO!$E$2:$E$1000,B12) -> 2 | H12: =COUNTIFS(VI_TRI_DO!$D$2:$D$1000,A12,VI_TRI_DO!$E$2:$E$1000,B12,VI_TRI_DO!$C$2:$C$1000,"Trống") -> 2 | I12: =IF(SUMPRODUCT((LOAI_XE!$A$2:$A$1000=A12)*(LOAI_XE!$B$2:$B$1000=B12))=1,"ĐẠT","LỆCH") -> ĐẠT | J12: =IF(SUMPRODUCT(--(BAI_DO_XE!$A$2:$A$1000=B12))>0,"ĐẠT","LỆCH") -> ĐẠT | K12: =IF(AND(D12>0,E12>0),"ĐẠT","LỆCH") -> ĐẠT
A13: XM | B13: BAI_Q7 | C13: Xe máy | D13: 5000 | E13: 170000 | F13: =INDEX(BAI_DO_XE!$B$2:$B$1000,MATCH(B13,BAI_DO_XE!$A$2:$A$1000,0)) -> Bãi xe SC VivoCity | G13: =COUNTIFS(VI_TRI_DO!$D$2:$D$1000,A13,VI_TRI_DO!$E$2:$E$1000,B13) -> 5 | H13: =COUNTIFS(VI_TRI_DO!$D$2:$D$1000,A13,VI_TRI_DO!$E$2:$E$1000,B13,VI_TRI_DO!$C$2:$C$1000,"Trống") -> 4 | I13: =IF(SUMPRODUCT((LOAI_XE!$A$2:$A$1000=A13)*(LOAI_XE!$B$2:$B$1000=B13))=1,"ĐẠT","LỆCH") -> ĐẠT | J13: =IF(SUMPRODUCT(--(BAI_DO_XE!$A$2:$A$1000=B13))>0,"ĐẠT","LỆCH") -> ĐẠT | K13: =IF(AND(D13>0,E13>0),"ĐẠT","LỆCH") -> ĐẠT
... A16: XM | B16: BAI_TB | C16: Xe máy | D16: 5000 | E16: 200000 | F16: =INDEX(BAI_DO_XE!$B$2:$B$1000,MATCH(B16,BAI_DO_XE!$A$2:$A$1000,0)) -> Bãi xe TCP Park - Sân bay Tân Sơn Nhất | G16: =COUNTIFS(VI_TRI_DO!$D$2:$D$1000,A16,VI_TRI_DO!$E$2:$E$1000,B16) -> 6 | H16: =COUNTIFS(VI_TRI_DO!$D$2:$D$1000,A16,VI_TRI_DO!$E$2:$E$1000,B16,VI_TRI_DO!$C$2:$C$1000,"Trống") -> 4 | I16: =IF(SUMPRODUCT((LOAI_XE!$A$2:$A$1000=A16)*(LOAI_XE!$B$2:$B$1000=B16))=1,"ĐẠT","LỆCH") -> ĐẠT | J16: =IF(SUMPRODUCT(--(BAI_DO_XE!$A$2:$A$1000=B16))>0,"ĐẠT","LỆCH") -> ĐẠT | K16: =IF(AND(D16>0,E16>0),"ĐẠT","LỆCH") -> ĐẠT

Sheet VI_TRI_DO
A1: MaViTri | B1: KhuVuc | C1: TrangThai | D1: MaLoaiXe | E1: MaBai | F1: LuotDangMo | G1: KT_PK | H1: KT_DinhDangMa | I1: KT_FK_LoaiXeTaiBai | J1: KT_DoDaiKhuVuc | K1: KT_MotXeMotO
A2: BT_OT_01 | B2: Hầm B2 - Zone A | C2: =IF(F2>0,"Đã đỗ","Trống") -> Đã đỗ | D2: OT | E2: BAI_BT | F2: =SUMPRODUCT((LUOT_GUI!$F$2:$F$1000=A2)*(LEN(LUOT_GUI!$E$2:$E$1000)=0)) -> 1 | G2: =IF(SUMPRODUCT(--(VI_TRI_DO!$A$2:$A$1000=A2))=1,"ĐẠT","LỆCH") -> ĐẠT | H2: =IF(LEFT(A2,LEN(SUBSTITUTE(E2,"BAI_",""))+LEN(D2)+2)=SUBSTITUTE(E2,"BAI_","")&"_"&D2&"_","ĐẠT","LỆCH") -> ĐẠT | I2: =IF(SUMPRODUCT((LOAI_XE!$A$2:$A$1000=D2)*(LOAI_XE!$B$2:$B$1000=E2))>0,"ĐẠT","LỆCH") -> ĐẠT | J2: =IF(LEN(B2)<=20,"ĐẠT","LỆCH") -> ĐẠT | K2: =IF(F2<=1,"ĐẠT","LỆCH") -> ĐẠT
A3: BT_OT_02 | B3: Hầm B2 - Zone A | C3: =IF(F3>0,"Đã đỗ","Trống") -> Trống | D3: OT | E3: BAI_BT | F3: =SUMPRODUCT((LUOT_GUI!$F$2:$F$1000=A3)*(LEN(LUOT_GUI!$E$2:$E$1000)=0)) -> 0 | G3: =IF(SUMPRODUCT(--(VI_TRI_DO!$A$2:$A$1000=A3))=1,"ĐẠT","LỆCH") -> ĐẠT | H3: =IF(LEFT(A3,LEN(SUBSTITUTE(E3,"BAI_",""))+LEN(D3)+2)=SUBSTITUTE(E3,"BAI_","")&"_"&D3&"_","ĐẠT","LỆCH") -> ĐẠT | I3: =IF(SUMPRODUCT((LOAI_XE!$A$2:$A$1000=D3)*(LOAI_XE!$B$2:$B$1000=E3))>0,"ĐẠT","LỆCH") -> ĐẠT | J3: =IF(LEN(B3)<=20,"ĐẠT","LỆCH") -> ĐẠT | K3: =IF(F3<=1,"ĐẠT","LỆCH") -> ĐẠT
A4: BT_OT_03 | B4: Hầm B2 - Zone B | C4: =IF(F4>0,"Đã đỗ","Trống") -> Trống | D4: OT | E4: BAI_BT | F4: =SUMPRODUCT((LUOT_GUI!$F$2:$F$1000=A4)*(LEN(LUOT_GUI!$E$2:$E$1000)=0)) -> 0 | G4: =IF(SUMPRODUCT(--(VI_TRI_DO!$A$2:$A$1000=A4))=1,"ĐẠT","LỆCH") -> ĐẠT | H4: =IF(LEFT(A4,LEN(SUBSTITUTE(E4,"BAI_",""))+LEN(D4)+2)=SUBSTITUTE(E4,"BAI_","")&"_"&D4&"_","ĐẠT","LỆCH") -> ĐẠT | I4: =IF(SUMPRODUCT((LOAI_XE!$A$2:$A$1000=D4)*(LOAI_XE!$B$2:$B$1000=E4))>0,"ĐẠT","LỆCH") -> ĐẠT | J4: =IF(LEN(B4)<=20,"ĐẠT","LỆCH") -> ĐẠT | K4: =IF(F4<=1,"ĐẠT","LỆCH") -> ĐẠT
A5: BT_OT_04 | B5: Hầm B2 - Zone B | C5: =IF(F5>0,"Đã đỗ","Trống") -> Trống | D5: OT | E5: BAI_BT | F5: =SUMPRODUCT((LUOT_GUI!$F$2:$F$1000=A5)*(LEN(LUOT_GUI!$E$2:$E$1000)=0)) -> 0 | G5: =IF(SUMPRODUCT(--(VI_TRI_DO!$A$2:$A$1000=A5))=1,"ĐẠT","LỆCH") -> ĐẠT | H5: =IF(LEFT(A5,LEN(SUBSTITUTE(E5,"BAI_",""))+LEN(D5)+2)=SUBSTITUTE(E5,"BAI_","")&"_"&D5&"_","ĐẠT","LỆCH") -> ĐẠT | I5: =IF(SUMPRODUCT((LOAI_XE!$A$2:$A$1000=D5)*(LOAI_XE!$B$2:$B$1000=E5))>0,"ĐẠT","LỆCH") -> ĐẠT | J5: =IF(LEN(B5)<=20,"ĐẠT","LỆCH") -> ĐẠT | K5: =IF(F5<=1,"ĐẠT","LỆCH") -> ĐẠT
A6: BT_XD_01 | B6: Hầm B1 - Zone E | C6: =IF(F6>0,"Đã đỗ","Trống") -> Trống | D6: XD | E6: BAI_BT | F6: =SUMPRODUCT((LUOT_GUI!$F$2:$F$1000=A6)*(LEN(LUOT_GUI!$E$2:$E$1000)=0)) -> 0 | G6: =IF(SUMPRODUCT(--(VI_TRI_DO!$A$2:$A$1000=A6))=1,"ĐẠT","LỆCH") -> ĐẠT | H6: =IF(LEFT(A6,LEN(SUBSTITUTE(E6,"BAI_",""))+LEN(D6)+2)=SUBSTITUTE(E6,"BAI_","")&"_"&D6&"_","ĐẠT","LỆCH") -> ĐẠT | I6: =IF(SUMPRODUCT((LOAI_XE!$A$2:$A$1000=D6)*(LOAI_XE!$B$2:$B$1000=E6))>0,"ĐẠT","LỆCH") -> ĐẠT | J6: =IF(LEN(B6)<=20,"ĐẠT","LỆCH") -> ĐẠT | K6: =IF(F6<=1,"ĐẠT","LỆCH") -> ĐẠT
A7: BT_XD_02 | B7: Hầm B1 - Zone E | C7: =IF(F7>0,"Đã đỗ","Trống") -> Trống | D7: XD | E7: BAI_BT | F7: =SUMPRODUCT((LUOT_GUI!$F$2:$F$1000=A7)*(LEN(LUOT_GUI!$E$2:$E$1000)=0)) -> 0 | G7: =IF(SUMPRODUCT(--(VI_TRI_DO!$A$2:$A$1000=A7))=1,"ĐẠT","LỆCH") -> ĐẠT | H7: =IF(LEFT(A7,LEN(SUBSTITUTE(E7,"BAI_",""))+LEN(D7)+2)=SUBSTITUTE(E7,"BAI_","")&"_"&D7&"_","ĐẠT","LỆCH") -> ĐẠT | I7: =IF(SUMPRODUCT((LOAI_XE!$A$2:$A$1000=D7)*(LOAI_XE!$B$2:$B$1000=E7))>0,"ĐẠT","LỆCH") -> ĐẠT | J7: =IF(LEN(B7)<=20,"ĐẠT","LỆCH") -> ĐẠT | K7: =IF(F7<=1,"ĐẠT","LỆCH") -> ĐẠT
A8: BT_XM_01 | B8: Hầm B1 - Zone 1 | C8: =IF(F8>0,"Đã đỗ","Trống") -> Trống | D8: XM | E8: BAI_BT | F8: =SUMPRODUCT((LUOT_GUI!$F$2:$F$1000=A8)*(LEN(LUOT_GUI!$E$2:$E$1000)=0)) -> 0 | G8: =IF(SUMPRODUCT(--(VI_TRI_DO!$A$2:$A$1000=A8))=1,"ĐẠT","LỆCH") -> ĐẠT | H8: =IF(LEFT(A8,LEN(SUBSTITUTE(E8,"BAI_",""))+LEN(D8)+2)=SUBSTITUTE(E8,"BAI_","")&"_"&D8&"_","ĐẠT","LỆCH") -> ĐẠT | I8: =IF(SUMPRODUCT((LOAI_XE!$A$2:$A$1000=D8)*(LOAI_XE!$B$2:$B$1000=E8))>0,"ĐẠT","LỆCH") -> ĐẠT | J8: =IF(LEN(B8)<=20,"ĐẠT","LỆCH") -> ĐẠT | K8: =IF(F8<=1,"ĐẠT","LỆCH") -> ĐẠT
A9: BT_XM_02 | B9: Hầm B1 - Zone 1 | C9: =IF(F9>0,"Đã đỗ","Trống") -> Trống | D9: XM | E9: BAI_BT | F9: =SUMPRODUCT((LUOT_GUI!$F$2:$F$1000=A9)*(LEN(LUOT_GUI!$E$2:$E$1000)=0)) -> 0 | G9: =IF(SUMPRODUCT(--(VI_TRI_DO!$A$2:$A$1000=A9))=1,"ĐẠT","LỆCH") -> ĐẠT | H9: =IF(LEFT(A9,LEN(SUBSTITUTE(E9,"BAI_",""))+LEN(D9)+2)=SUBSTITUTE(E9,"BAI_","")&"_"&D9&"_","ĐẠT","LỆCH") -> ĐẠT | I9: =IF(SUMPRODUCT((LOAI_XE!$A$2:$A$1000=D9)*(LOAI_XE!$B$2:$B$1000=E9))>0,"ĐẠT","LỆCH") -> ĐẠT | J9: =IF(LEN(B9)<=20,"ĐẠT","LỆCH") -> ĐẠT | K9: =IF(F9<=1,"ĐẠT","LỆCH") -> ĐẠT
A10: BT_XM_03 | B10: Hầm B1 - Zone 2 | C10: =IF(F10>0,"Đã đỗ","Trống") -> Trống | D10: XM | E10: BAI_BT | F10: =SUMPRODUCT((LUOT_GUI!$F$2:$F$1000=A10)*(LEN(LUOT_GUI!$E$2:$E$1000)=0)) -> 0 | G10: =IF(SUMPRODUCT(--(VI_TRI_DO!$A$2:$A$1000=A10))=1,"ĐẠT","LỆCH") -> ĐẠT | H10: =IF(LEFT(A10,LEN(SUBSTITUTE(E10,"BAI_",""))+LEN(D10)+2)=SUBSTITUTE(E10,"BAI_","")&"_"&D10&"_","ĐẠT","LỆCH") -> ĐẠT | I10: =IF(SUMPRODUCT((LOAI_XE!$A$2:$A$1000=D10)*(LOAI_XE!$B$2:$B$1000=E10))>0,"ĐẠT","LỆCH") -> ĐẠT | J10: =IF(LEN(B10)<=20,"ĐẠT","LỆCH") -> ĐẠT | K10: =IF(F10<=1,"ĐẠT","LỆCH") -> ĐẠT
A11: BT_XM_04 | B11: Hầm B1 - Zone 2 | C11: =IF(F11>0,"Đã đỗ","Trống") -> Trống | D11: XM | E11: BAI_BT | F11: =SUMPRODUCT((LUOT_GUI!$F$2:$F$1000=A11)*(LEN(LUOT_GUI!$E$2:$E$1000)=0)) -> 0 | G11: =IF(SUMPRODUCT(--(VI_TRI_DO!$A$2:$A$1000=A11))=1,"ĐẠT","LỆCH") -> ĐẠT | H11: =IF(LEFT(A11,LEN(SUBSTITUTE(E11,"BAI_",""))+LEN(D11)+2)=SUBSTITUTE(E11,"BAI_","")&"_"&D11&"_","ĐẠT","LỆCH") -> ĐẠT | I11: =IF(SUMPRODUCT((LOAI_XE!$A$2:$A$1000=D11)*(LOAI_XE!$B$2:$B$1000=E11))>0,"ĐẠT","LỆCH") -> ĐẠT | J11: =IF(LEN(B11)<=20,"ĐẠT","LỆCH") -> ĐẠT | K11: =IF(F11<=1,"ĐẠT","LỆCH") -> ĐẠT
A12: BT_XM_05 | B12: Hầm B1 - Zone 3 | C12: =IF(F12>0,"Đã đỗ","Trống") -> Trống | D12: XM | E12: BAI_BT | F12: =SUMPRODUCT((LUOT_GUI!$F$2:$F$1000=A12)*(LEN(LUOT_GUI!$E$2:$E$1000)=0)) -> 0 | G12: =IF(SUMPRODUCT(--(VI_TRI_DO!$A$2:$A$1000=A12))=1,"ĐẠT","LỆCH") -> ĐẠT | H12: =IF(LEFT(A12,LEN(SUBSTITUTE(E12,"BAI_",""))+LEN(D12)+2)=SUBSTITUTE(E12,"BAI_","")&"_"&D12&"_","ĐẠT","LỆCH") -> ĐẠT | I12: =IF(SUMPRODUCT((LOAI_XE!$A$2:$A$1000=D12)*(LOAI_XE!$B$2:$B$1000=E12))>0,"ĐẠT","LỆCH") -> ĐẠT | J12: =IF(LEN(B12)<=20,"ĐẠT","LỆCH") -> ĐẠT | K12: =IF(F12<=1,"ĐẠT","LỆCH") -> ĐẠT
A13: BT_XM_06 | B13: Hầm B1 - Zone 3 | C13: =IF(F13>0,"Đã đỗ","Trống") -> Trống | D13: XM | E13: BAI_BT | F13: =SUMPRODUCT((LUOT_GUI!$F$2:$F$1000=A13)*(LEN(LUOT_GUI!$E$2:$E$1000)=0)) -> 0 | G13: =IF(SUMPRODUCT(--(VI_TRI_DO!$A$2:$A$1000=A13))=1,"ĐẠT","LỆCH") -> ĐẠT | H13: =IF(LEFT(A13,LEN(SUBSTITUTE(E13,"BAI_",""))+LEN(D13)+2)=SUBSTITUTE(E13,"BAI_","")&"_"&D13&"_","ĐẠT","LỆCH") -> ĐẠT | I13: =IF(SUMPRODUCT((LOAI_XE!$A$2:$A$1000=D13)*(LOAI_XE!$B$2:$B$1000=E13))>0,"ĐẠT","LỆCH") -> ĐẠT | J13: =IF(LEN(B13)<=20,"ĐẠT","LỆCH") -> ĐẠT | K13: =IF(F13<=1,"ĐẠT","LỆCH") -> ĐẠT
... A61: TB_XM_06 | B61: Tầng lửng - Xe máy | C61: =IF(F61>0,"Đã đỗ","Trống") -> Trống | D61: XM | E61: BAI_TB | F61: =SUMPRODUCT((LUOT_GUI!$F$2:$F$1000=A61)*(LEN(LUOT_GUI!$E$2:$E$1000)=0)) -> 0 | G61: =IF(SUMPRODUCT(--(VI_TRI_DO!$A$2:$A$1000=A61))=1,"ĐẠT","LỆCH") -> ĐẠT | H61: =IF(LEFT(A61,LEN(SUBSTITUTE(E61,"BAI_",""))+LEN(D61)+2)=SUBSTITUTE(E61,"BAI_","")&"_"&D61&"_","ĐẠT","LỆCH") -> ĐẠT | I61: =IF(SUMPRODUCT((LOAI_XE!$A$2:$A$1000=D61)*(LOAI_XE!$B$2:$B$1000=E61))>0,"ĐẠT","LỆCH") -> ĐẠT | J61: =IF(LEN(B61)<=20,"ĐẠT","LỆCH") -> ĐẠT | K61: =IF(F61<=1,"ĐẠT","LỆCH") -> ĐẠT

Sheet THE_XE
A1: MaThe | B1: MaBai | C1: LoaiThe | D1: TrangThai | E1: NgayCap | F1: NgayCapCoDinh | G1: NgayCapTruocNapNgay | H1: LuotDangMo | I1: MaVe | J1: NgayHetHanVe | K1: TrangThaiVe | L1: MaBaiApDungVe | M1: KetQuaQuetCheckIn | N1: KT_PK | O1: KT_DinhDangMa | P1: KT_FK_MaBai | Q1: KT_TheThangCoVe | R1: KT_MotLuotMo | S1: KT_TheHongKhongDangDo
A2: THE0001 | B2: BAI_Q1 | C2: Lượt | D2: Hoạt động | E2: =IF(LEN(G2)>0,INT(ThoiDiemNap)-G2,F2) -> 46023 | F2: 46023 | H2: =SUMPRODUCT((LUOT_GUI!$B$2:$B$1000=A2)*(LEN(LUOT_GUI!$E$2:$E$1000)=0)) -> 1 | I2: =IFERROR(INDEX(VE_THANG!$A$2:$A$1000,MATCH(A2,VE_THANG!$B$2:$B$1000,0)),"") | J2: =IFERROR(INDEX(VE_THANG!$G$2:$G$1000,MATCH(A2,VE_THANG!$B$2:$B$1000,0)),"") | K2: =IFERROR(INDEX(VE_THANG!$H$2:$H$1000,MATCH(A2,VE_THANG!$B$2:$B$1000,0)),"") | L2: =IFERROR(INDEX(VE_THANG!$I$2:$I$1000,MATCH(A2,VE_THANG!$B$2:$B$1000,0)),"") | M2: =IF(OR(D2="Bị khóa",D2="Mất"),"CHẶN 50002 - Thẻ khóa/mất",IF(AND(C2="Tháng",I2<>"",OR(AND(ISNUMBER(J2),J2<INT(ThoiDiemTinh)),K2="Hết hạn")),"CHẶN 50003 - Vé tháng hết hạn",IF(H2>0,"Đang trong bãi - quét để RA",IF(L2="","Cho phép VÀO tại "&B2,IF(L2="ALL","Cho phép VÀO mọi bãi (vé toàn chuỗi)","Cho phép VÀO chỉ tại "&L2))))) -> Đang trong bãi - quét để RA | N2: =IF(SUMPRODUCT(--(THE_XE!$A$2:$A$1000=A2))=1,"ĐẠT","LỆCH") -> ĐẠT | O2: =IF(AND(LEN(A2)=7,LEFT(A2,3)="THE",ISNUMBER(-MID(A2,4,4)),ISERROR(FIND(".",MID(A2,4,4)))),"ĐẠT","LỆCH") -> ĐẠT | P2: =IF(SUMPRODUCT(--(BAI_DO_XE!$A$2:$A$1000=B2))>0,"ĐẠT","LỆCH") -> ĐẠT | Q2: =IF(C2="Tháng",IF(I2<>"","ĐẠT","LỆCH"),"ĐẠT") -> ĐẠT | R2: =IF(H2<=1,"ĐẠT","LỆCH") -> ĐẠT | S2: =IF(D2="Hoạt động","ĐẠT",IF(H2=0,"ĐẠT","LỆCH")) -> ĐẠT
A3: THE0002 | B3: BAI_Q1 | C3: Tháng | D3: Hoạt động | E3: =IF(LEN(G3)>0,INT(ThoiDiemNap)-G3,F3) -> 46023 | F3: 46023 | H3: =SUMPRODUCT((LUOT_GUI!$B$2:$B$1000=A3)*(LEN(LUOT_GUI!$E$2:$E$1000)=0)) -> 1 | I3: =IFERROR(INDEX(VE_THANG!$A$2:$A$1000,MATCH(A3,VE_THANG!$B$2:$B$1000,0)),"") -> V0001 | J3: =IFERROR(INDEX(VE_THANG!$G$2:$G$1000,MATCH(A3,VE_THANG!$B$2:$B$1000,0)),"") -> 46388 | K3: =IFERROR(INDEX(VE_THANG!$H$2:$H$1000,MATCH(A3,VE_THANG!$B$2:$B$1000,0)),"") -> Hoạt động | L3: =IFERROR(INDEX(VE_THANG!$I$2:$I$1000,MATCH(A3,VE_THANG!$B$2:$B$1000,0)),"") -> BAI_Q1 | M3: =IF(OR(D3="Bị khóa",D3="Mất"),"CHẶN 50002 - Thẻ khóa/mất",IF(AND(C3="Tháng",I3<>"",OR(AND(ISNUMBER(J3),J3<INT(ThoiDiemTinh)),K3="Hết hạn")),"CHẶN 50003 - Vé tháng hết hạn",IF(H3>0,"Đang trong bãi - quét để RA",IF(L3="","Cho phép VÀO tại "&B3,IF(L3="ALL","Cho phép VÀO mọi bãi (vé toàn chuỗi)","Cho phép VÀO chỉ tại "&L3))))) -> Đang trong bãi - quét để RA | N3: =IF(SUMPRODUCT(--(THE_XE!$A$2:$A$1000=A3))=1,"ĐẠT","LỆCH") -> ĐẠT | O3: =IF(AND(LEN(A3)=7,LEFT(A3,3)="THE",ISNUMBER(-MID(A3,4,4)),ISERROR(FIND(".",MID(A3,4,4)))),"ĐẠT","LỆCH") -> ĐẠT | P3: =IF(SUMPRODUCT(--(BAI_DO_XE!$A$2:$A$1000=B3))>0,"ĐẠT","LỆCH") -> ĐẠT | Q3: =IF(C3="Tháng",IF(I3<>"","ĐẠT","LỆCH"),"ĐẠT") -> ĐẠT | R3: =IF(H3<=1,"ĐẠT","LỆCH") -> ĐẠT | S3: =IF(D3="Hoạt động","ĐẠT",IF(H3=0,"ĐẠT","LỆCH")) -> ĐẠT
A4: THE0003 | B4: BAI_Q1 | C4: Lượt | D4: Hoạt động | E4: =IF(LEN(G4)>0,INT(ThoiDiemNap)-G4,F4) -> 46027 | F4: 46027 | H4: =SUMPRODUCT((LUOT_GUI!$B$2:$B$1000=A4)*(LEN(LUOT_GUI!$E$2:$E$1000)=0)) -> 0 | I4: =IFERROR(INDEX(VE_THANG!$A$2:$A$1000,MATCH(A4,VE_THANG!$B$2:$B$1000,0)),"") | J4: =IFERROR(INDEX(VE_THANG!$G$2:$G$1000,MATCH(A4,VE_THANG!$B$2:$B$1000,0)),"") | K4: =IFERROR(INDEX(VE_THANG!$H$2:$H$1000,MATCH(A4,VE_THANG!$B$2:$B$1000,0)),"") | L4: =IFERROR(INDEX(VE_THANG!$I$2:$I$1000,MATCH(A4,VE_THANG!$B$2:$B$1000,0)),"") | M4: =IF(OR(D4="Bị khóa",D4="Mất"),"CHẶN 50002 - Thẻ khóa/mất",IF(AND(C4="Tháng",I4<>"",OR(AND(ISNUMBER(J4),J4<INT(ThoiDiemTinh)),K4="Hết hạn")),"CHẶN 50003 - Vé tháng hết hạn",IF(H4>0,"Đang trong bãi - quét để RA",IF(L4="","Cho phép VÀO tại "&B4,IF(L4="ALL","Cho phép VÀO mọi bãi (vé toàn chuỗi)","Cho phép VÀO chỉ tại "&L4))))) -> Cho phép VÀO tại BAI_Q1 | N4: =IF(SUMPRODUCT(--(THE_XE!$A$2:$A$1000=A4))=1,"ĐẠT","LỆCH") -> ĐẠT | O4: =IF(AND(LEN(A4)=7,LEFT(A4,3)="THE",ISNUMBER(-MID(A4,4,4)),ISERROR(FIND(".",MID(A4,4,4)))),"ĐẠT","LỆCH") -> ĐẠT | P4: =IF(SUMPRODUCT(--(BAI_DO_XE!$A$2:$A$1000=B4))>0,"ĐẠT","LỆCH") -> ĐẠT | Q4: =IF(C4="Tháng",IF(I4<>"","ĐẠT","LỆCH"),"ĐẠT") -> ĐẠT | R4: =IF(H4<=1,"ĐẠT","LỆCH") -> ĐẠT | S4: =IF(D4="Hoạt động","ĐẠT",IF(H4=0,"ĐẠT","LỆCH")) -> ĐẠT
A5: THE0004 | B5: BAI_Q1 | C5: Tháng | D5: Hoạt động | E5: =IF(LEN(G5)>0,INT(ThoiDiemNap)-G5,F5) -> 46032 | F5: 46032 | H5: =SUMPRODUCT((LUOT_GUI!$B$2:$B$1000=A5)*(LEN(LUOT_GUI!$E$2:$E$1000)=0)) -> 0 | I5: =IFERROR(INDEX(VE_THANG!$A$2:$A$1000,MATCH(A5,VE_THANG!$B$2:$B$1000,0)),"") -> V0002 | J5: =IFERROR(INDEX(VE_THANG!$G$2:$G$1000,MATCH(A5,VE_THANG!$B$2:$B$1000,0)),"") -> 46305 | K5: =IFERROR(INDEX(VE_THANG!$H$2:$H$1000,MATCH(A5,VE_THANG!$B$2:$B$1000,0)),"") -> Hoạt động | L5: =IFERROR(INDEX(VE_THANG!$I$2:$I$1000,MATCH(A5,VE_THANG!$B$2:$B$1000,0)),"") -> BAI_Q1 | M5: =IF(OR(D5="Bị khóa",D5="Mất"),"CHẶN 50002 - Thẻ khóa/mất",IF(AND(C5="Tháng",I5<>"",OR(AND(ISNUMBER(J5),J5<INT(ThoiDiemTinh)),K5="Hết hạn")),"CHẶN 50003 - Vé tháng hết hạn",IF(H5>0,"Đang trong bãi - quét để RA",IF(L5="","Cho phép VÀO tại "&B5,IF(L5="ALL","Cho phép VÀO mọi bãi (vé toàn chuỗi)","Cho phép VÀO chỉ tại "&L5))))) -> Cho phép VÀO chỉ tại BAI_Q1 | N5: =IF(SUMPRODUCT(--(THE_XE!$A$2:$A$1000=A5))=1,"ĐẠT","LỆCH") -> ĐẠT | O5: =IF(AND(LEN(A5)=7,LEFT(A5,3)="THE",ISNUMBER(-MID(A5,4,4)),ISERROR(FIND(".",MID(A5,4,4)))),"ĐẠT","LỆCH") -> ĐẠT | P5: =IF(SUMPRODUCT(--(BAI_DO_XE!$A$2:$A$1000=B5))>0,"ĐẠT","LỆCH") -> ĐẠT | Q5: =IF(C5="Tháng",IF(I5<>"","ĐẠT","LỆCH"),"ĐẠT") -> ĐẠT | R5: =IF(H5<=1,"ĐẠT","LỆCH") -> ĐẠT | S5: =IF(D5="Hoạt động","ĐẠT",IF(H5=0,"ĐẠT","LỆCH")) -> ĐẠT
A6: THE0005 | B6: BAI_Q1 | C6: Lượt | D6: Bị khóa | E6: =IF(LEN(G6)>0,INT(ThoiDiemNap)-G6,F6) -> 46034 | F6: 46034 | H6: =SUMPRODUCT((LUOT_GUI!$B$2:$B$1000=A6)*(LEN(LUOT_GUI!$E$2:$E$1000)=0)) -> 0 | I6: =IFERROR(INDEX(VE_THANG!$A$2:$A$1000,MATCH(A6,VE_THANG!$B$2:$B$1000,0)),"") | J6: =IFERROR(INDEX(VE_THANG!$G$2:$G$1000,MATCH(A6,VE_THANG!$B$2:$B$1000,0)),"") | K6: =IFERROR(INDEX(VE_THANG!$H$2:$H$1000,MATCH(A6,VE_THANG!$B$2:$B$1000,0)),"") | L6: =IFERROR(INDEX(VE_THANG!$I$2:$I$1000,MATCH(A6,VE_THANG!$B$2:$B$1000,0)),"") | M6: =IF(OR(D6="Bị khóa",D6="Mất"),"CHẶN 50002 - Thẻ khóa/mất",IF(AND(C6="Tháng",I6<>"",OR(AND(ISNUMBER(J6),J6<INT(ThoiDiemTinh)),K6="Hết hạn")),"CHẶN 50003 - Vé tháng hết hạn",IF(H6>0,"Đang trong bãi - quét để RA",IF(L6="","Cho phép VÀO tại "&B6,IF(L6="ALL","Cho phép VÀO mọi bãi (vé toàn chuỗi)","Cho phép VÀO chỉ tại "&L6))))) -> CHẶN 50002 - Thẻ khóa/mất | N6: =IF(SUMPRODUCT(--(THE_XE!$A$2:$A$1000=A6))=1,"ĐẠT","LỆCH") -> ĐẠT | O6: =IF(AND(LEN(A6)=7,LEFT(A6,3)="THE",ISNUMBER(-MID(A6,4,4)),ISERROR(FIND(".",MID(A6,4,4)))),"ĐẠT","LỆCH") -> ĐẠT | P6: =IF(SUMPRODUCT(--(BAI_DO_XE!$A$2:$A$1000=B6))>0,"ĐẠT","LỆCH") -> ĐẠT | Q6: =IF(C6="Tháng",IF(I6<>"","ĐẠT","LỆCH"),"ĐẠT") -> ĐẠT | R6: =IF(H6<=1,"ĐẠT","LỆCH") -> ĐẠT | S6: =IF(D6="Hoạt động","ĐẠT",IF(H6=0,"ĐẠT","LỆCH")) -> ĐẠT
A7: THE0006 | B7: BAI_Q1 | C7: Lượt | D7: Mất | E7: =IF(LEN(G7)>0,INT(ThoiDiemNap)-G7,F7) -> 46037 | F7: 46037 | H7: =SUMPRODUCT((LUOT_GUI!$B$2:$B$1000=A7)*(LEN(LUOT_GUI!$E$2:$E$1000)=0)) -> 0 | I7: =IFERROR(INDEX(VE_THANG!$A$2:$A$1000,MATCH(A7,VE_THANG!$B$2:$B$1000,0)),"") | J7: =IFERROR(INDEX(VE_THANG!$G$2:$G$1000,MATCH(A7,VE_THANG!$B$2:$B$1000,0)),"") | K7: =IFERROR(INDEX(VE_THANG!$H$2:$H$1000,MATCH(A7,VE_THANG!$B$2:$B$1000,0)),"") | L7: =IFERROR(INDEX(VE_THANG!$I$2:$I$1000,MATCH(A7,VE_THANG!$B$2:$B$1000,0)),"") | M7: =IF(OR(D7="Bị khóa",D7="Mất"),"CHẶN 50002 - Thẻ khóa/mất",IF(AND(C7="Tháng",I7<>"",OR(AND(ISNUMBER(J7),J7<INT(ThoiDiemTinh)),K7="Hết hạn")),"CHẶN 50003 - Vé tháng hết hạn",IF(H7>0,"Đang trong bãi - quét để RA",IF(L7="","Cho phép VÀO tại "&B7,IF(L7="ALL","Cho phép VÀO mọi bãi (vé toàn chuỗi)","Cho phép VÀO chỉ tại "&L7))))) -> CHẶN 50002 - Thẻ khóa/mất | N7: =IF(SUMPRODUCT(--(THE_XE!$A$2:$A$1000=A7))=1,"ĐẠT","LỆCH") -> ĐẠT | O7: =IF(AND(LEN(A7)=7,LEFT(A7,3)="THE",ISNUMBER(-MID(A7,4,4)),ISERROR(FIND(".",MID(A7,4,4)))),"ĐẠT","LỆCH") -> ĐẠT | P7: =IF(SUMPRODUCT(--(BAI_DO_XE!$A$2:$A$1000=B7))>0,"ĐẠT","LỆCH") -> ĐẠT | Q7: =IF(C7="Tháng",IF(I7<>"","ĐẠT","LỆCH"),"ĐẠT") -> ĐẠT | R7: =IF(H7<=1,"ĐẠT","LỆCH") -> ĐẠT | S7: =IF(D7="Hoạt động","ĐẠT",IF(H7=0,"ĐẠT","LỆCH")) -> ĐẠT
A8: THE0007 | B8: BAI_Q3 | C8: Lượt | D8: Hoạt động | E8: =IF(LEN(G8)>0,INT(ThoiDiemNap)-G8,F8) -> 46023 | F8: 46023 | H8: =SUMPRODUCT((LUOT_GUI!$B$2:$B$1000=A8)*(LEN(LUOT_GUI!$E$2:$E$1000)=0)) -> 1 | I8: =IFERROR(INDEX(VE_THANG!$A$2:$A$1000,MATCH(A8,VE_THANG!$B$2:$B$1000,0)),"") | J8: =IFERROR(INDEX(VE_THANG!$G$2:$G$1000,MATCH(A8,VE_THANG!$B$2:$B$1000,0)),"") | K8: =IFERROR(INDEX(VE_THANG!$H$2:$H$1000,MATCH(A8,VE_THANG!$B$2:$B$1000,0)),"") | L8: =IFERROR(INDEX(VE_THANG!$I$2:$I$1000,MATCH(A8,VE_THANG!$B$2:$B$1000,0)),"") | M8: =IF(OR(D8="Bị khóa",D8="Mất"),"CHẶN 50002 - Thẻ khóa/mất",IF(AND(C8="Tháng",I8<>"",OR(AND(ISNUMBER(J8),J8<INT(ThoiDiemTinh)),K8="Hết hạn")),"CHẶN 50003 - Vé tháng hết hạn",IF(H8>0,"Đang trong bãi - quét để RA",IF(L8="","Cho phép VÀO tại "&B8,IF(L8="ALL","Cho phép VÀO mọi bãi (vé toàn chuỗi)","Cho phép VÀO chỉ tại "&L8))))) -> Đang trong bãi - quét để RA | N8: =IF(SUMPRODUCT(--(THE_XE!$A$2:$A$1000=A8))=1,"ĐẠT","LỆCH") -> ĐẠT | O8: =IF(AND(LEN(A8)=7,LEFT(A8,3)="THE",ISNUMBER(-MID(A8,4,4)),ISERROR(FIND(".",MID(A8,4,4)))),"ĐẠT","LỆCH") -> ĐẠT | P8: =IF(SUMPRODUCT(--(BAI_DO_XE!$A$2:$A$1000=B8))>0,"ĐẠT","LỆCH") -> ĐẠT | Q8: =IF(C8="Tháng",IF(I8<>"","ĐẠT","LỆCH"),"ĐẠT") -> ĐẠT | R8: =IF(H8<=1,"ĐẠT","LỆCH") -> ĐẠT | S8: =IF(D8="Hoạt động","ĐẠT",IF(H8=0,"ĐẠT","LỆCH")) -> ĐẠT
A9: THE0008 | B9: BAI_Q3 | C9: Tháng | D9: Hoạt động | E9: =IF(LEN(G9)>0,INT(ThoiDiemNap)-G9,F9) -> 46025 | F9: 46025 | H9: =SUMPRODUCT((LUOT_GUI!$B$2:$B$1000=A9)*(LEN(LUOT_GUI!$E$2:$E$1000)=0)) -> 0 | I9: =IFERROR(INDEX(VE_THANG!$A$2:$A$1000,MATCH(A9,VE_THANG!$B$2:$B$1000,0)),"") -> V0003 | J9: =IFERROR(INDEX(VE_THANG!$G$2:$G$1000,MATCH(A9,VE_THANG!$B$2:$B$1000,0)),"") -> 46056 | K9: =IFERROR(INDEX(VE_THANG!$H$2:$H$1000,MATCH(A9,VE_THANG!$B$2:$B$1000,0)),"") -> Hết hạn | L9: =IFERROR(INDEX(VE_THANG!$I$2:$I$1000,MATCH(A9,VE_THANG!$B$2:$B$1000,0)),"") -> BAI_Q3 | M9: =IF(OR(D9="Bị khóa",D9="Mất"),"CHẶN 50002 - Thẻ khóa/mất",IF(AND(C9="Tháng",I9<>"",OR(AND(ISNUMBER(J9),J9<INT(ThoiDiemTinh)),K9="Hết hạn")),"CHẶN 50003 - Vé tháng hết hạn",IF(H9>0,"Đang trong bãi - quét để RA",IF(L9="","Cho phép VÀO tại "&B9,IF(L9="ALL","Cho phép VÀO mọi bãi (vé toàn chuỗi)","Cho phép VÀO chỉ tại "&L9))))) -> CHẶN 50003 - Vé tháng hết hạn | N9: =IF(SUMPRODUCT(--(THE_XE!$A$2:$A$1000=A9))=1,"ĐẠT","LỆCH") -> ĐẠT | O9: =IF(AND(LEN(A9)=7,LEFT(A9,3)="THE",ISNUMBER(-MID(A9,4,4)),ISERROR(FIND(".",MID(A9,4,4)))),"ĐẠT","LỆCH") -> ĐẠT | P9: =IF(SUMPRODUCT(--(BAI_DO_XE!$A$2:$A$1000=B9))>0,"ĐẠT","LỆCH") -> ĐẠT | Q9: =IF(C9="Tháng",IF(I9<>"","ĐẠT","LỆCH"),"ĐẠT") -> ĐẠT | R9: =IF(H9<=1,"ĐẠT","LỆCH") -> ĐẠT | S9: =IF(D9="Hoạt động","ĐẠT",IF(H9=0,"ĐẠT","LỆCH")) -> ĐẠT
A10: THE0009 | B10: BAI_Q3 | C10: Lượt | D10: Hoạt động | E10: =IF(LEN(G10)>0,INT(ThoiDiemNap)-G10,F10) -> 46027 | F10: 46027 | H10: =SUMPRODUCT((LUOT_GUI!$B$2:$B$1000=A10)*(LEN(LUOT_GUI!$E$2:$E$1000)=0)) -> 0 | I10: =IFERROR(INDEX(VE_THANG!$A$2:$A$1000,MATCH(A10,VE_THANG!$B$2:$B$1000,0)),"") | J10: =IFERROR(INDEX(VE_THANG!$G$2:$G$1000,MATCH(A10,VE_THANG!$B$2:$B$1000,0)),"") | K10: =IFERROR(INDEX(VE_THANG!$H$2:$H$1000,MATCH(A10,VE_THANG!$B$2:$B$1000,0)),"") | L10: =IFERROR(INDEX(VE_THANG!$I$2:$I$1000,MATCH(A10,VE_THANG!$B$2:$B$1000,0)),"") | M10: =IF(OR(D10="Bị khóa",D10="Mất"),"CHẶN 50002 - Thẻ khóa/mất",IF(AND(C10="Tháng",I10<>"",OR(AND(ISNUMBER(J10),J10<INT(ThoiDiemTinh)),K10="Hết hạn")),"CHẶN 50003 - Vé tháng hết hạn",IF(H10>0,"Đang trong bãi - quét để RA",IF(L10="","Cho phép VÀO tại "&B10,IF(L10="ALL","Cho phép VÀO mọi bãi (vé toàn chuỗi)","Cho phép VÀO chỉ tại "&L10))))) -> Cho phép VÀO tại BAI_Q3 | N10: =IF(SUMPRODUCT(--(THE_XE!$A$2:$A$1000=A10))=1,"ĐẠT","LỆCH") -> ĐẠT | O10: =IF(AND(LEN(A10)=7,LEFT(A10,3)="THE",ISNUMBER(-MID(A10,4,4)),ISERROR(FIND(".",MID(A10,4,4)))),"ĐẠT","LỆCH") -> ĐẠT | P10: =IF(SUMPRODUCT(--(BAI_DO_XE!$A$2:$A$1000=B10))>0,"ĐẠT","LỆCH") -> ĐẠT | Q10: =IF(C10="Tháng",IF(I10<>"","ĐẠT","LỆCH"),"ĐẠT") -> ĐẠT | R10: =IF(H10<=1,"ĐẠT","LỆCH") -> ĐẠT | S10: =IF(D10="Hoạt động","ĐẠT",IF(H10=0,"ĐẠT","LỆCH")) -> ĐẠT
A11: THE0010 | B11: BAI_Q3 | C11: Tháng | D11: Hoạt động | E11: =IF(LEN(G11)>0,INT(ThoiDiemNap)-G11,F11) -> 46030 | F11: 46030 | H11: =SUMPRODUCT((LUOT_GUI!$B$2:$B$1000=A11)*(LEN(LUOT_GUI!$E$2:$E$1000)=0)) -> 0 | I11: =IFERROR(INDEX(VE_THANG!$A$2:$A$1000,MATCH(A11,VE_THANG!$B$2:$B$1000,0)),"") -> V0004 | J11: =IFERROR(INDEX(VE_THANG!$G$2:$G$1000,MATCH(A11,VE_THANG!$B$2:$B$1000,0)),"") -> 46334 | K11: =IFERROR(INDEX(VE_THANG!$H$2:$H$1000,MATCH(A11,VE_THANG!$B$2:$B$1000,0)),"") -> Hoạt động | L11: =IFERROR(INDEX(VE_THANG!$I$2:$I$1000,MATCH(A11,VE_THANG!$B$2:$B$1000,0)),"") -> ALL | M11: =IF(OR(D11="Bị khóa",D11="Mất"),"CHẶN 50002 - Thẻ khóa/mất",IF(AND(C11="Tháng",I11<>"",OR(AND(ISNUMBER(J11),J11<INT(ThoiDiemTinh)),K11="Hết hạn")),"CHẶN 50003 - Vé tháng hết hạn",IF(H11>0,"Đang trong bãi - quét để RA",IF(L11="","Cho phép VÀO tại "&B11,IF(L11="ALL","Cho phép VÀO mọi bãi (vé toàn chuỗi)","Cho phép VÀO chỉ tại "&L11))))) -> Cho phép VÀO mọi bãi (vé toàn chuỗi) | N11: =IF(SUMPRODUCT(--(THE_XE!$A$2:$A$1000=A11))=1,"ĐẠT","LỆCH") -> ĐẠT | O11: =IF(AND(LEN(A11)=7,LEFT(A11,3)="THE",ISNUMBER(-MID(A11,4,4)),ISERROR(FIND(".",MID(A11,4,4)))),"ĐẠT","LỆCH") -> ĐẠT | P11: =IF(SUMPRODUCT(--(BAI_DO_XE!$A$2:$A$1000=B11))>0,"ĐẠT","LỆCH") -> ĐẠT | Q11: =IF(C11="Tháng",IF(I11<>"","ĐẠT","LỆCH"),"ĐẠT") -> ĐẠT | R11: =IF(H11<=1,"ĐẠT","LỆCH") -> ĐẠT | S11: =IF(D11="Hoạt động","ĐẠT",IF(H11=0,"ĐẠT","LỆCH")) -> ĐẠT
